Workbook
Name Belen_de_los_Andaquies: '[1]BD listas'!$C$3:$C$18
Name Municipios: '[1]BD listas'!$B$3:$B$13
Name resguardos: '[1]BD listas'!$I$2:$I$12

Sheet HERRAMIENTA_SEGUIMIENTO
A9: PROYECTO DE RESTAURACIÓN ECOLÓGICA, REHABILITACIÓN Y RECUPERACIÓN DE ECOSISTEMAS DEGRADADOS
A10: HERRAMIENTA DE SEGUIMIENTO PROCESOS DE IMPLEMETACIÓN

Sheet T4_2025
C2: Indicadores de avances de implementaciones
A5: Código Predio | B5: Famila | C5: Municipio | D5: Vereda | E5: Hectáreas del predio | F5: Colinos (piña y plátano) | V5: Cacao | AK5: Forestales (viveros comunitarios) | AZ5: Frutales | BO5: 1. No. Nacimientos a aislar | BW5: Observaciones | BX5: 2. Área de nacimiento aislar (ha) | CF5: Observaciones | CG5: 3. Área de fuente hídrica a aislar (ha) | CP5: Observaciones | CQ5: 4. Sistemas silvopastoriles (Ha) | CY5: Observaciones | CZ5: 5. Cercas vivas (metros) | DH5: Observación | DI5: 6. División de Potrero (Número Potreros) | DR5: Observación | DS5: 7. # Potreros con Árboles Dispersos | DZ5: Observación | EA5: 8. Enriquecimiento de SAF (ha) | EI5: Observación | EJ5: 9. Implementación de SAF (ha) | ER5: Observación | ES5: 10. Corredor de Conectividad (ha) | FA5: Observación | FB5: 11. Adecuación de Biodigestor | FJ5: Observación | FK5: 12. Acueducto Ganadero (Metros) | FS5: Observación | FT5: 13. Abejas (# Colmenas) | GA5: Observación | GB5: 14. Enriquecimiento Rastrojo (Ha) | GJ5: Observación | GK5: 15. Enriquecimiento de Bosque (ha) | GS5: Observación | GT5: 16. Restauración de área degradada | HB5: Observación | HC5: 17. # Huertas sin cubierta | HK5: Observación | HL5: 18. # Huerta bajo cubierta | HT5: Observación | HU5: 19. # Gallinas Criollas | IC5: Observación | ID5: 20. Estufas Ecologicas | IE5: Observación | IF5: 21. Acumulado en restauración Ecológica | IN5: 22. Acumulado en rehabilitación Ecológica | IV5: 23. Cumplimiento Acuerdo de Conservación | IX5: Observación
F6: Barrera viva establecida control de la erosión (m) | G6: Meta | H6: Entregados T2 | I6: Entregados T3 | J6: Entregados T4 | K6: Entregados T1_2025 | L6: Entregados T2_2025 | M6: Entregados T3_2025 | N6: Entregados T4_2025 | O6: Sembrados T2 | P6: Sembrados T3 | Q6: Sembrados T4 | R6: Sembrado T1_2025 | S6: Sembrado T2_2025 | T6: Sembrado T3_2025 | U6: Sembrado T4_2025 | V6: Meta | W6: Entregados T2 | X6: Entregados T3 | Y6: Entregados T4 | Z6: Entregados T1_2025 | AA6: Entregados T2_2025 | AB6: Entregados T3_2025 | AC6: Entregados T4_2025 | AD6: Sembrados T2 | AE6: Sembrados T3 | AF6: Sembrados T4 | AG6: Sembrado T1_2025 | AH6: Sembrado T2_2025 | AI6: Sembrado T3_2025 | AJ6: Sembrado T4_2025 | AK6: Meta | AL6: Entregados T2 | AM6: Entregados T3 | AN6: Entregados T4 | AO6: Entregados T1_2025 | AP6: Entregados T2_2025 | AQ6: Entregados T3_2025 | AR6: Entregados T4_2025 | AS6: Sembrados T2 | AT6: Sembrados T3 | AU6: Sembrados T4 | AV6: Sembrado T1_2025 | AW6: Sembrado T2_2025 | AX6: Sembrado T3_2025 | AY6: Sembrado T4_2025 | AZ6: Meta | BA6: Entregados T2 | BB6: Entregados T3 | BC6: Entregados T4 | BD6: Entregados T1_2025 | BE6: Entregados T2_2025 | BF6: Entregados T3_2025 | BG6: Entregados T4_2025 | BH6: Sembrados T2 | BI6: Sembrados T3 | BJ6: Sembrados T4 | BK6: Sembrado T1_2025 | BL6: Sembrado T2_2025 | BM6: Sembrado T3_2025 | BN6: Sembrado T4_2025 | BO6: Meta | BP6: Avance T2 | BQ6: Avance T3 | BR6: Avance T3 | BS6: Avance T1_2025 | BT6: Avance T2_2025 | BU6: Avance T3_2025 | BV6: Avance T4_2025 | BX6: Meta | BY6: Avance T2 | BZ6: Avance T3 | CA6: Avance T4 | CB6: Avance T1_2025 | CC6: Avance T2_2025 | CD6: Avance T3_2025 | CE6: Avance T4_2025 | CG6: Meta | CH6: Avance T2 | CI6: Avance T3 | CJ6: Avance T4 | CK6: Avance T1_2025 | CL6: Avance T2_2025 | CM6: Avance T3_2025 | CN6: Avance T4_2025 | CQ6: Meta | CR6: Avance T2 | CS6: Avance T3 | CT6: Avance T4 | CU6: Avance_T1_2025 | CV6: Avance T2_2025 | CW6: Avance T3_2025 | CX6: Avance T4_2025 | CZ6: Meta | DA6: Avance T2 | DB6: Avance T3 | DC6: Avance T4 | DD6: Avance_T1_2025 | DE6: Avance T2_2025 | DF6: Avance T3_2025 | DG6: Avance T4_2025 | DI6: # Potreros Iniciales | DJ6: Meta # Potreros | DK6: Avance T2 | DL6: Avance T3 | DM6: Avance T4 | DN6: Avance_T1_2025 | DO6: Avance T2_2025 | DP6: Avance T3_2025 | DQ6: Avance T4_2025 | DS6: Avance T2 | DT6: Avance T3 | DU6: Avance T4 | DV6: Avance_T1_2025 | DW6: Avance T2_2025 | DX6: Avance T3_2025 | DY6: Avance T4_2025 | EA6: Meta | EB6: Avance T2 | EC6: Avance T3 | ED6: Avance T4 | EE6: Avance_T1_2025 | EF6: Avance T2_2025 | EG6: Avance T3_2025 | EH6: Avance T4_2025 | EJ6: Meta | EK6: Avance T2 | EL6: Avance T3 | EM6: Avance T4 | EN6: Avance_T1_2025 | EO6: Avance T2_2025 | EP6: Avance T3_2025 | EQ6: Avance T4_2025 | ES6: Meta | ET6: Avance T2 | EU6: Avance T3 | EV6: Avance T4 | EW6: Avance_T1_2025 | EX6: Avance T2_2025 | EY6: Avance T3_2025 | EZ6: Avance T4_2025 | FB6: Meta | FC6: Avance T2 | FD6: Avance T3 | FE6: Avance T4 | FF6: Avance_T1_2025 | FG6: Avance T2_2025 | FH6: Avance T3_2025 | FI6: Avance T4_2025 | FK6: Meta | FL6: Avance T2 | FM6: Avance T3 | FN6: Avance T4 | FO6: Avance_T1_2025 | FP6: Avance T2_2025 | FQ6: Avance T3_2025 | FR6: Avance T4_2025 | FT6: Avance T2 | FU6: Avance T3 | FV6: Avance T4 | FW6: Avance_T1_2025 | FX6: Avance T2_2025 | FY6: Avance T3_2025 | FZ6: Avance T4_2025 | GB6: Meta | GC6: Avance T2 | GD6: Avance T3 | GE6: Avance T4 | GF6: Avance_T1_2025 | GG6: Avance T2_2025 | GH6: Avance T3_2025 | GI6: Avance T4_2025 | GK6: Meta | GL6: Avance T2 | GM6: Avance T3 | GN6: Avance T4 | GO6: Avance_T1_2025 | GP6: Avance T2_2025 | GQ6: Avance T3_2025 | GR6: Avance T4_2025 | GT6: Meta | GU6: Avance T2 | GV6: Avance T3 | GW6: Avance T4 | GX6: Avance_T1_2025 | GY6: Avance T2_2025 | GZ6: Avance T3_2025 | HA6: Avance T4_2025 | HC6: Meta | HD6: Avance T2 | HE6: Avance T3 | HF6: Avance T4 | HG6: Avance_T1_2025 | HH6: Avance T2_2025 | HI6: Avance T3_2025 | HJ6: Avance T4_2025 | HL6: Meta | HM6: Avance T2 | HN6: Avance T3 | HO6: Avance T4 | HP6: Avance_T1_2025 | HQ6: Avance T2_2025 | HR6: Avance T3_2025 | HS6: Avance T4_2025 | HU6: Meta | HV6: Avance T2 | HW6: Avance T3 | HX6: Avance T4 | HY6: Avance_T1_2025 | HZ6: Avance T2_2025 | IA6: Avance T3_2025 | IB6: Avance T4_2025 | IF6: Meta | IG6: Avance T2 | IH6: Avance T3 | II6: Avance T4 | IJ6: Avance T1_2025 | IK6: Avance T2_2025 | IL6: Avance T3_2025 | IM6: Avance T4_2025 | IN6: Meta | IO6: Avance T2 | IP6: Avance T3 | IQ6: Avance T4 | IR6: Avance T1_2025 | IS6: Avance T2_2025 | IT6: Avance T3_2025 | IU6: Avance T4_2025 | IV6: Meta | IW6: % de cumplimiento
A7: 1 | B7: Hernán Manuel Castrillo Moscote | C7: Dibulla | D7: Caney (Comunidad De Santa Rita De La Sierra ) | E7: 20.1 | F7: 0 | G7: 750 | I7: 750 | O7: 0 | P7: 750 | V7: 0 | W7: 0 | AD7: 0 | AK7: 13332 | AL7: 0 | AM7: 0 | AN7: 936 | AP7: 6000 | AR7: 0 | AS7: 0 | AW7: 6000 | AX7: 936 | AZ7: 200 | BA7: 200 | BG7: 0 | BH7: 0 | BI7: 113 | BJ7: 87 | BN7: 0 | CG7: 2.3 | CH7: 0 | CL7: 1.2 | CN7: 1.1 | EJ7: 2.7 | EK7: 0.3 | EL7: 0.7 | EM7: 0.7 | EO7: 1 | EQ7: 0 | IF7: =BX7+CG7+GB7+GK7+GT7 -> 2.3 | IG7: =BY7+CH7+GC7+GL7+GU7 -> 0 | IH7: =BZ7+CI7+GD7+GM7+GV7 -> 0 | II7: =CA7+CJ7+GE7+GN7+GW7 -> 0 | IJ7: =CB7+CK7+GF7+GO7+GX7 -> 0 | IK7: =CC7+CL7+GG7+GP7+GY7 -> 1.2 | IL7: =CD7+CM7+GH7+GQ7+GZ7 -> 0 | IM7: =CE7+CN7+GI7+GR7+HA7 -> 1.1 | IN7: =CQ7+EA7+EJ7+ES7 -> 2.7 | IO7: =CR7+EB7+EK7+ET7 -> 0.3 | IP7: =CS7+EC7+EL7+EU7 -> 0.7 | IQ7: =CT7+ED7+EM7+EV7 -> 0.7 | IR7: =CU7+EE7+EN7+EW7 -> 0 | IS7: =CV7+EF7+EO7+EX7 -> 1 | IT7: =CW7+EG7+EP7+EY7 -> 0 | IU7: =CX7+EH7+EQ7+EZ7 -> 0 | IV7: 0 | IW7: 1
A8: 2 | B8: Rebeca Hesther Rolón Sierra | C8: Dibulla | D8: Caney (Comunidad De Santa Rita De La Sierra ) | E8: 20.1 | F8: 0 | G8: =500+250 -> 750 | I8: 500 | O8: 0 | P8: 500 | V8: 633 | X8: 633 | AA8: 633 | AD8: 0 | AF8: 120 | AH8: 633 | AJ8: 513 | AK8: 1198 | AL8: 0 | AN8: 200 | AQ8: 998 | AR8: 200 | AS8: 0 | AY8: 1398 | AZ8: 0 | BA8: 0 | BG8: 30 | BH8: 0 | BN8: 30 | CG8: 2.2 | CH8: 0 | CL8: 0.5 | CN8: 1.7 | EJ8: 3 | EK8: 0 | EO8: 3 | EQ8: 0 | IF8: =BX8+CG8+GB8+GK8+GT8 -> 2.2 | IG8: =BY8+CH8+GC8+GL8+GU8 -> 0 | IH8: =BZ8+CI8+GD8+GM8+GV8 -> 0 | II8: =CA8+CJ8+GE8+GN8+GW8 -> 0 | IJ8: =CB8+CK8+GF8+GO8+GX8 -> 0 | IK8: =CC8+CL8+GG8+GP8+GY8 -> 0.5 | IL8: =CD8+CM8+GH8+GQ8+GZ8 -> 0 | IM8: =CE8+CN8+GI8+GR8+HA8 -> 1.7 | IN8: =CQ8+EA8+EJ8+ES8 -> 3 | IO8: =CR8+EB8+EK8+ET8 -> 0 | IP8: =CS8+EC8+EL8+EU8 -> 0 | IQ8: =CT8+ED8+EM8+EV8 -> 0 | IR8: =CU8+EE8+EN8+EW8 -> 0 | IS8: =CV8+EF8+EO8+EX8 -> 3 | IT8: =CW8+EG8+EP8+EY8 -> 0 | IU8: =CX8+EH8+EQ8+EZ8 -> 0 | IV8: 3.7 | IW8: 1
A9: 3 | B9: Cristo Humberto Guarín Rincón | C9: Dibulla | D9: Caney (Comunidad De Santa Rita De La Sierra ) | E9: 19.6 | F9: 12.5 | G9: =1500+600 -> 2100 | I9: 1500 | O9: 750 | P9: 750 | V9: 703 | W9: 0 | X9: 703 | AD9: 0 | AF9: 120 | AJ9: 583 | AK9: 2917 | AL9: 0 | AN9: 599 | AQ9: 1413 | AR9: 599 | AS9: 0 | AY9: 2611 | AZ9: 113 | BA9: 113 | BG9: 0 | BH9: 0 | BI9: 50 | BJ9: 63 | BN9: 0 | CG9: 2.4 | CH9: 0 | CL9: 0.5 | CN9: 1.9 | EJ9: 2.6 | EK9: 0.5 | EL9: 0.5 | EP9: 1 | EQ9: 0.6 | IF9: =BX9+CG9+GB9+GK9+GT9 -> 2.4 | IG9: =BY9+CH9+GC9+GL9+GU9 -> 0 | IH9: =BZ9+CI9+GD9+GM9+GV9 -> 0 | II9: =CA9+CJ9+GE9+GN9+GW9 -> 0 | IJ9: =CB9+CK9+GF9+GO9+GX9 -> 0 | IK9: =CC9+CL9+GG9+GP9+GY9 -> 0.5 | IL9: =CD9+CM9+GH9+GQ9+GZ9 -> 0 | IM9: =CE9+CN9+GI9+GR9+HA9 -> 1.9 | IN9: =CQ9+EA9+EJ9+ES9 -> 2.6 | IO9: =CR9+EB9+EK9+ET9 -> 0.5 | IP9: =CS9+EC9+EL9+EU9 -> 0.5 | IQ9: =CT9+ED9+EM9+EV9 -> 0 | IR9: =CU9+EE9+EN9+EW9 -> 0 | IS9: =CV9+EF9+EO9+EX9 -> 0 | IT9: =CW9+EG9+EP9+EY9 -> 1 | IU9: =CX9+EH9+EQ9+EZ9 -> 0.6 | IV9: 0 | IW9: 1
A10: 4 | B10: Wilson Guarín Pérez | C10: Dibulla | D10: Caney (Comunidad De Santa Rita De La Sierra ) | E10: 17.9 | F10: 12.5 | G10: =1500+800 -> 2300 | I10: 1500 | O10: 750 | P10: 750 | V10: 0 | W10: 0 | AD10: 0 | AK10: 2670 | AL10: 0 | AN10: 299 | AQ10: 1803 | AR10: 299 | AS10: 0 | AY10: 2401 | AZ10: 289 | BA10: 113 | BG10: 0 | BH10: 0 | BI10: 50 | BJ10: 63 | BN10: 0 | CG10: 0.8 | CL10: 0 | CN10: 0.8 | EJ10: 2 | EK10: 0 | EL10: 0.5 | EM10: 0.5 | EO10: 0.5 | EP10: 0.5 | EQ10: 0 | IF10: =BX10+CG10+GB10+GK10+GT10 -> 0.8 | IG10: =BY10+CH10+GC10+GL10+GU10 -> 0 | IH10: =BZ10+CI10+GD10+GM10+GV10 -> 0 | II10: =CA10+CJ10+GE10+GN10+GW10 -> 0 | IJ10: =CB10+CK10+GF10+GO10+GX10 -> 0 | IK10: =CC10+CL10+GG10+GP10+GY10 -> 0 | IL10: =CD10+CM10+GH10+GQ10+GZ10 -> 0 | IM10: =CE10+CN10+GI10+GR10+HA10 -> 0.8 | IN10: =CQ10+EA10+EJ10+ES10 -> 2 | IO10: =CR10+EB10+EK10+ET10 -> 0 | IP10: =CS10+EC10+EL10+EU10 -> 0.5 | IQ10: =CT10+ED10+EM10+EV10 -> 0.5 | IR10: =CU10+EE10+EN10+EW10 -> 0 | IS10: =CV10+EF10+EO10+EX10 -> 0.5 | IT10: =CW10+EG10+EP10+EY10 -> 0.5 | IU10: =CX10+EH10+EQ10+EZ10 -> 0 | IV10: 1.6 | IW10: 1
A11: 5 | B11: Jorge Elías Fornieles Navarro | C11: Dibulla | D11: Caney (Comunidad De Santa Rita De La Sierra ) | E11: 18 | F11: 4 | G11: 750 | I11: 750 | O11: 250 | P11: 0 | Q11: 250 | T11: 250 | V11: 0 | W11: 0 | AD11: 0 | AK11: 2540 | AL11: 0 | AN11: 820 | AO11: 720 | AP11: 1540 | AR11: 0 | AS11: 0 | AW11: 1540 | AX11: 980 | AY11: 560 | AZ11: 125 | BA11: 125 | BG11: 0 | BH11: 0 | BI11: 0 | BM11: 125 | BN11: 0 | CG11: 1.6 | CL11: 0.5 | CN11: 1.1 | EJ11: 1 | EK11: 0 | EL11: 0.5 | EM11: 0.5 | EQ11: 0 | IF11: =BX11+CG11+GB11+GK11+GT11 -> 1.6 | IG11: =BY11+CH11+GC11+GL11+GU11 -> 0 | IH11: =BZ11+CI11+GD11+GM11+GV11 -> 0 | II11: =CA11+CJ11+GE11+GN11+GW11 -> 0 | IJ11: =CB11+CK11+GF11+GO11+GX11 -> 0 | IK11: =CC11+CL11+GG11+GP11+GY11 -> 0.5 | IL11: =CD11+CM11+GH11+GQ11+GZ11 -> 0 | IM11: =CE11+CN11+GI11+GR11+HA11 -> 1.1 | IN11: =CQ11+EA11+EJ11+ES11 -> 1 | IO11: =CR11+EB11+EK11+ET11 -> 0 | IP11: =CS11+EC11+EL11+EU11 -> 0.5 | IQ11: =CT11+ED11+EM11+EV11 -> 0.5 | IR11: =CU11+EE11+EN11+EW11 -> 0 | IS11: =CV11+EF11+EO11+EX11 -> 0 | IT11: =CW11+EG11+EP11+EY11 -> 0 | IU11: =CX11+EH11+EQ11+EZ11 -> 0 | IV11: 3.9 | IW11: 1
A12: 6 | B12: Nuri Contreras Baldovino | C12: Dibulla | D12: Comunidad de Santa Rita | E12: 17.9 | F12: 29.8 | G12: =1000+600 -> 1600 | I12: 1000 | O12: 0 | P12: 0 | Q12: 1000 | V12: 0 | W12: 0 | AD12: 0 | AK12: 2119 | AL12: 0 | AN12: 205 | AQ12: 1914 | AR12: 205 | AS12: 0 | AY12: 2324 | AZ12: 113 | BA12: 113 | BG12: 0 | BH12: 0 | BI12: 50 | BJ12: 63 | BN12: 0 | CG12: 1.1 | CL12: 0.5 | CN12: 0.6 | EJ12: 2 | EK12: 0 | EL12: 0.5 | EQ12: 1.5 | IF12: =BX12+CG12+GB12+GK12+GT12 -> 1.1 | IG12: =BY12+CH12+GC12+GL12+GU12 -> 0 | IH12: =BZ12+CI12+GD12+GM12+GV12 -> 0 | II12: =CA12+CJ12+GE12+GN12+GW12 -> 0 | IJ12: =CB12+CK12+GF12+GO12+GX12 -> 0 | IK12: =CC12+CL12+GG12+GP12+GY12 -> 0.5 | IL12: =CD12+CM12+GH12+GQ12+GZ12 -> 0 | IM12: =CE12+CN12+GI12+GR12+HA12 -> 0.6 | IN12: =CQ12+EA12+EJ12+ES12 -> 2 | IO12: =CR12+EB12+EK12+ET12 -> 0 | IP12: =CS12+EC12+EL12+EU12 -> 0.5 | IQ12: =CT12+ED12+EM12+EV12 -> 0 | IR12: =CU12+EE12+EN12+EW12 -> 0 | IS12: =CV12+EF12+EO12+EX12 -> 0 | IT12: =CW12+EG12+EP12+EY12 -> 0 | IU12: =CX12+EH12+EQ12+EZ12 -> 1.5 | IV12: 0 | IW12: 1
A13: 7 | B13: Pastora María Cantillo Vergel | C13: Dibulla | D13: Larga La Vida | E13: 86.7 | F13: 8.4 | G13: 1500 | I13: 1500 | O13: 500 | P13: 1000 | V13: 703 | W13: 0 | Y13: 703 | AD13: 0 | AF13: 120 | AG13: 240 | AJ13: 343 | AK13: 4784 | AL13: 2079 | AN13: 288 | AR13: 2417 | AS13: 0 | AT13: 1370 | AY13: 3414 | AZ13: 50 | BA13: 0 | BG13: 0 | BH13: 0 | BN13: 0 | CG13: 1.6 | CH13: 0 | CJ13: 1 | CL13: 0 | CN13: 0.6 | EJ13: 9 | EK13: 0.6 | EL13: 0.3 | EP13: 3 | EQ13: 5.1 | IF13: =BX13+CG13+GB13+GK13+GT13 -> 1.6 | IG13: =BY13+CH13+GC13+GL13+GU13 -> 0 | IH13: =BZ13+CI13+GD13+GM13+GV13 -> 0 | II13: =CA13+CJ13+GE13+GN13+GW13 -> 1 | IJ13: =CB13+CK13+GF13+GO13+GX13 -> 0 | IK13: =CC13+CL13+GG13+GP13+GY13 -> 0 | IL13: =CD13+CM13+GH13+GQ13+GZ13 -> 0 | IM13: =CE13+CN13+GI13+GR13+HA13 -> 0.6 | IN13: =CQ13+EA13+EJ13+ES13 -> 9 | IO13: =CR13+EB13+EK13+ET13 -> 0.6 | IP13: =CS13+EC13+EL13+EU13 -> 0.3 | IQ13: =CT13+ED13+EM13+EV13 -> 0 | IR13: =CU13+EE13+EN13+EW13 -> 0 | IS13: =CV13+EF13+EO13+EX13 -> 0 | IT13: =CW13+EG13+EP13+EY13 -> 3 | IU13: =CX13+EH13+EQ13+EZ13 -> 5.1 | IV13: 20 | IW13: 1
A14: 8 | B14: Carlos Antonio Cantillo Romero | C14: Dibulla | D14: Larga La Vida | E14: 19.3 | F14: 25 | G14: 1500 | I14: 1500 | O14: 1500 | V14: 703 | W14: 0 | Y14: 703 | AD14: 0 | AF14: 300 | AG14: 120 | AJ14: 283 | AK14: 6284 | AL14: 1774 | AN14: 625 | AR14: 3885 | AS14: 0 | AT14: 700 | AU14: 918 | AY14: 4666 | AZ14: 50 | BA14: 0 | BG14: 0 | BH14: 0 | BN14: 0 | CG14: 1.8 | CH14: 0 | CJ14: 1 | CL14: 0 | CN14: 0.8 | EJ14: 3.8 | EK14: 0.6 | EL14: 0.3 | EP14: 2 | EQ14: 0.9 | IF14: =BX14+CG14+GB14+GK14+GT14 -> 1.8 | IG14: =BY14+CH14+GC14+GL14+GU14 -> 0 | IH14: =BZ14+CI14+GD14+GM14+GV14 -> 0 | II14: =CA14+CJ14+GE14+GN14+GW14 -> 1 | IJ14: =CB14+CK14+GF14+GO14+GX14 -> 0 | IK14: =CC14+CL14+GG14+GP14+GY14 -> 0 | IL14: =CD14+CM14+GH14+GQ14+GZ14 -> 0 | IM14: =CE14+CN14+GI14+GR14+HA14 -> 0.8 | IN14: =CQ14+EA14+EJ14+ES14 -> 3.8 | IO14: =CR14+EB14+EK14+ET14 -> 0.6 | IP14: =CS14+EC14+EL14+EU14 -> 0.3 | IQ14: =CT14+ED14+EM14+EV14 -> 0 | IR14: =CU14+EE14+EN14+EW14 -> 0 | IS14: =CV14+EF14+EO14+EX14 -> 0 | IT14: =CW14+EG14+EP14+EY14 -> 2 | IU14: =CX14+EH14+EQ14+EZ14 -> 0.9 | IV14: 5 | IW14: 1
A15: 9 | B15: Edwin Elías Nieves Mendoza | C15: Dibulla | D15: Larga La Vida | E15: 10.1 | F15: 25 | G15: =1500+300 -> 1800 | I15: 1500 | O15: 1500 | P15: 0 | V15: 703 | W15: 0 | X15: 703 | AD15: 0 | AF15: 703 | AK15: 6838 | AL15: 5038 | AN15: 335 | AQ15: 1465 | AR15: 0 | AS15: 5038 | AY15: 1800 | AZ15: 175 | BA15: 0 | BF15: 120 | BG15: 0 | BH15: 0 | BM15: 120 | BN15: 0 | CG15: 2.5 | CJ15: 2.5 | CL15: 0 | CN15: 0 | EJ15: 3.3 | EK15: 0.6 | EL15: 0.4 | EP15: 1 | EQ15: 1.3 | FV15: 1 | HC15: 1 | HH15: 1 | IF15: =BX15+CG15+GB15+GK15+GT15 -> 2.5 | IG15: =BY15+CH15+GC15+GL15+GU15 -> 0 | IH15: =BZ15+CI15+GD15+GM15+GV15 -> 0 | II15: =CA15+CJ15+GE15+GN15+GW15 -> 2.5 | IJ15: =CB15+CK15+GF15+GO15+GX15 -> 0 | IK15: =CC15+CL15+GG15+GP15+GY15 -> 0 | IL15: =CD15+CM15+GH15+GQ15+GZ15 -> 0 | IM15: =CE15+CN15+GI15+GR15+HA15 -> 0 | IN15: =CQ15+EA15+EJ15+ES15 -> 3.3 | IO15: =CR15+EB15+EK15+ET15 -> 0.6 | IP15: =CS15+EC15+EL15+EU15 -> 0.4 | IQ15: =CT15+ED15+EM15+EV15 -> 0 | IR15: =CU15+EE15+EN15+EW15 -> 0 | IS15: =CV15+EF15+EO15+EX15 -> 0 | IT15: =CW15+EG15+EP15+EY15 -> 1 | IU15: =CX15+EH15+EQ15+EZ15 -> 1.3 | IV15: 0.8 | IW15: 1
A16: 10 | B16: Lilibeth Nieves Mendoza | C16: Dibulla | D16: Larga La Vida | E16: 6.5 | F16: 12.5 | G16: =1500+300 -> 1800 | I16: 1500 | O16: 750 | P16: 750 | V16: 703 | W16: 0 | X16: 703 | AD16: 0 | AJ16: 703 | AK16: 3456 | AL16: 0 | AM16: 80 | AO16: 2606 | AQ16: 770 | AR16: 0 | AS16: 0 | AT16: 0 | AU16: 80 | AV16: 2606 | AY16: 770 | AZ16: 175 | BA16: 0 | BG16: 100 | BH16: 0 | BN16: 100 | CG16: 0.7 | CJ16: 0.7 | CL16: 0.4 | CN16: 0 | EJ16: 2.3 | EK16: 0.3 | EL16: 0.5 | EQ16: 1.5 | IF16: =BX16+CG16+GB16+GK16+GT16 -> 0.7 | IG16: =BY16+CH16+GC16+GL16+GU16 -> 0 | IH16: =BZ16+CI16+GD16+GM16+GV16 -> 0 | II16: =CA16+CJ16+GE16+GN16+GW16 -> 0.7 | IJ16: =CB16+CK16+GF16+GO16+GX16 -> 0 | IK16: =CC16+CL16+GG16+GP16+GY16 -> 0.4 | IL16: =CD16+CM16+GH16+GQ16+GZ16 -> 0 | IM16: =CE16+CN16+GI16+GR16+HA16 -> 0 | IN16: =CQ16+EA16+EJ16+ES16 -> 2.3 | IO16: =CR16+EB16+EK16+ET16 -> 0.3 | IP16: =CS16+EC16+EL16+EU16 -> 0.5 | IQ16: =CT16+ED16+EM16+EV16 -> 0 | IR16: =CU16+EE16+EN16+EW16 -> 0 | IS16: =CV16+EF16+EO16+EX16 -> 0 | IT16: =CW16+EG16+EP16+EY16 -> 0 | IU16: =CX16+EH16+EQ16+EZ16 -> 1.5 | IV16: 0 | IW16: 1
A17: 11 | B17: José Francisco López Gómez | C17: Dibulla | D17: Larga La Vida | E17: 6.5 | F17: 10.8 | G17: =1500+300 -> 1800 | I17: 1500 | O17: 0 | P17: 600 | Q17: 900 | V17: 0 | W17: 0 | AD17: 0 | AK17: 4358 | AL17: 2761 | AN17: 291 | AQ17: 597 | AR17: 709 | AS17: 2761 | AY17: 1597 | AZ17: 275 | BA17: 100 | BG17: 60 | BH17: 100 | BN17: 60 | CG17: 0.3 | CH17: 1 | CL17: 0 | CN17: 0 | EJ17: 2.4 | EK17: 0.3 | EL17: 0.7 | EM17: 0.5 | EO17: 0.9 | EQ17: 0 | FV17: 1 | IF17: =BX17+CG17+GB17+GK17+GT17 -> 0.3 | IG17: =BY17+CH17+GC17+GL17+GU17 -> 1 | IH17: =BZ17+CI17+GD17+GM17+GV17 -> 0 | II17: =CA17+CJ17+GE17+GN17+GW17 -> 0 | IJ17: =CB17+CK17+GF17+GO17+GX17 -> 0 | IK17: =CC17+CL17+GG17+GP17+GY17 -> 0 | IL17: =CD17+CM17+GH17+GQ17+GZ17 -> 0 | IM17: =CE17+CN17+GI17+GR17+HA17 -> 0 | IN17: =CQ17+EA17+EJ17+ES17 -> 2.4 | IO17: =CR17+EB17+EK17+ET17 -> 0.3 | IP17: =CS17+EC17+EL17+EU17 -> 0.7 | IQ17: =CT17+ED17+EM17+EV17 -> 0.5 | IR17: =CU17+EE17+EN17+EW17 -> 0 | IS17: =CV17+EF17+EO17+EX17 -> 0.9 | IT17: =CW17+EG17+EP17+EY17 -> 0 | IU17: =CX17+EH17+EQ17+EZ17 -> 0 | IV17: 0 | IW17: 1
A18: 12 | B18: Fanio Manuel Castillo Yépez | C18: Dibulla | D18: Larga La Vida | E18: 8.4 | F18: 12.5 | G18: =750+300 -> 1050 | I18: 750 | O18: 750 | V18: 0 | W18: 0 | AD18: 0 | AK18: 4663 | AL18: 2595 | AO18: 1181 | AR18: 887 | AS18: 2595 | AV18: 1181 | AY18: 887 | AZ18: 150 | BA18: 150 | BG18: 0 | BH18: 0 | BI18: 50 | BJ18: 100 | BN18: 0 | CG18: 0.4 | CJ18: 0.4 | CL18: 0 | CN18: 0 | CQ18: 1.8 | CV18: 1.8 | EJ18: 1 | EK18: 0.3 | EL18: 0.7 | EQ18: 0 | IF18: =BX18+CG18+GB18+GK18+GT18 -> 0.4 | IG18: =BY18+CH18+GC18+GL18+GU18 -> 0 | IH18: =BZ18+CI18+GD18+GM18+GV18 -> 0 | II18: =CA18+CJ18+GE18+GN18+GW18 -> 0.4 | IJ18: =CB18+CK18+GF18+GO18+GX18 -> 0 | IK18: =CC18+CL18+GG18+GP18+GY18 -> 0 | IL18: =CD18+CM18+GH18+GQ18+GZ18 -> 0 | IM18: =CE18+CN18+GI18+GR18+HA18 -> 0 | IN18: =CQ18+EA18+EJ18+ES18 -> 2.8 | IO18: =CR18+EB18+EK18+ET18 -> 0.3 | IP18: =CS18+EC18+EL18+EU18 -> 0.7 | IQ18: =CT18+ED18+EM18+EV18 -> 0 | IR18: =CU18+EE18+EN18+EW18 -> 0 | IS18: =CV18+EF18+EO18+EX18 -> 1.8 | IT18: =CW18+EG18+EP18+EY18 -> 0 | IU18: =CX18+EH18+EQ18+EZ18 -> 0 | IV18: 0 | IW18: 1
A19: 13 | B19: Dager Castillo Yépez | C19: Dibulla | D19: Larga La Vida | E19: 6.8 | F19: 12.5 | G19: 750 | I19: 750 | O19: 750 | V19: 0 | W19: 0 | AD19: 0 | AK19: 2830 | AL19: 1530 | AQ19: 1300 | AR19: 0 | AS19: 1000 | AU19: 530 | AY19: 1300 | AZ19: 175 | BA19: 100 | BG19: 20 | BH19: 100 | BN19: 20 | CG19: 0.6 | CJ19: 0.6 | CL19: 0 | CN19: 0 | EJ19: 1.1 | EK19: 0.3 | EL19: 0.8 | EQ19: 0 | IF19: =BX19+CG19+GB19+GK19+GT19 -> 0.6 | IG19: =BY19+CH19+GC19+GL19+GU19 -> 0 | IH19: =BZ19+CI19+GD19+GM19+GV19 -> 0 | II19: =CA19+CJ19+GE19+GN19+GW19 -> 0.6 | IJ19: =CB19+CK19+GF19+GO19+GX19 -> 0 | IK19: =CC19+CL19+GG19+GP19+GY19 -> 0 | IL19: =CD19+CM19+GH19+GQ19+GZ19 -> 0 | IM19: =CE19+CN19+GI19+GR19+HA19 -> 0 | IN19: =CQ19+EA19+EJ19+ES19 -> 1.1 | IO19: =CR19+EB19+EK19+ET19 -> 0.3 | IP19: =CS19+EC19+EL19+EU19 -> 0.8 | IQ19: =CT19+ED19+EM19+EV19 -> 0 | IR19: =CU19+EE19+EN19+EW19 -> 0 | IS19: =CV19+EF19+EO19+EX19 -> 0 | IT19: =CW19+EG19+EP19+EY19 -> 0 | IU19: =CX19+EH19+EQ19+EZ19 -> 0 | IV19: 0.8 | IW19: 1
A20: 14 | B20: Mauricio Pérez | C20: Dibulla | D20: Larga La Vida | E20: 15.8 | F20: 26.3 | G20: 1125 | I20: 1125 | O20: 0 | P20: 0 | Q20: 1125 | V20: 0 | W20: 0 | AD20: 0 | AK20: 3009 | AL20: 0 | AN20: 100 | AO20: 2909 | AQ20: 0 | AR20: 0 | AS20: 0 | AU20: 100 | AW20: 2909 | AY20: 0 | AZ20: 351 | BA20: 117 | BF20: 100 | BG20: 0 | BH20: 0 | BI20: 0 | BJ20: 0 | BM20: 117 | BN20: 100 | CG20: 0.6 | CJ20: 0.6 | CL20: 0 | CN20: 0 | EJ20: 1.4 | EK20: 0 | EL20: 0.4 | EP20: 1 | EQ20: 0 | IF20: =BX20+CG20+GB20+GK20+GT20 -> 0.6 | IG20: =BY20+CH20+GC20+GL20+GU20 -> 0 | IH20: =BZ20+CI20+GD20+GM20+GV20 -> 0 | II20: =CA20+CJ20+GE20+GN20+GW20 -> 0.6 | IJ20: =CB20+CK20+GF20+GO20+GX20 -> 0 | IK20: =CC20+CL20+GG20+GP20+GY20 -> 0 | IL20: =CD20+CM20+GH20+GQ20+GZ20 -> 0 | IM20: =CE20+CN20+GI20+GR20+HA20 -> 0 | IN20: =CQ20+EA20+EJ20+ES20 -> 1.4 | IO20: =CR20+EB20+EK20+ET20 -> 0 | IP20: =CS20+EC20+EL20+EU20 -> 0.4 | IQ20: =CT20+ED20+EM20+EV20 -> 0 | IR20: =CU20+EE20+EN20+EW20 -> 0 | IS20: =CV20+EF20+EO20+EX20 -> 0 | IT20: =CW20+EG20+EP20+EY20 -> 1 | IU20: =CX20+EH20+EQ20+EZ20 -> 0 | IV20: 1.6 | IW20: 1
A21: 15 | B21: Aura Esther Miranda Herrera | C21: Dibulla | D21: Larga La Vida | E21: 16.2 | F21: 27 | G21: 750 | I21: 0 | J21: 750 | O21: 0 | Q21: 750 | V21: 0 | W21: 0 | AD21: 0 | AK21: 2514 | AL21: 0 | AN21: 50 | AP21: 1000 | AR21: 0 | AS21: 0 | AW21: 1050 | AY21: 0 | AZ21: 175 | BA21: 100 | BG21: 0 | BH21: 100 | BJ21: 0 | BN21: 0 | CG21: 0.5 | CL21: 0.5 | CN21: 0 | EJ21: 3 | EK21: 0 | EL21: 0.1 | EP21: 2 | EQ21: 0.9 | IF21: =BX21+CG21+GB21+GK21+GT21 -> 0.5 | IG21: =BY21+CH21+GC21+GL21+GU21 -> 0 | IH21: =BZ21+CI21+GD21+GM21+GV21 -> 0 | II21: =CA21+CJ21+GE21+GN21+GW21 -> 0 | IJ21: =CB21+CK21+GF21+GO21+GX21 -> 0 | IK21: =CC21+CL21+GG21+GP21+GY21 -> 0.5 | IL21: =CD21+CM21+GH21+GQ21+GZ21 -> 0 | IM21: =CE21+CN21+GI21+GR21+HA21 -> 0 | IN21: =CQ21+EA21+EJ21+ES21 -> 3 | IO21: =CR21+EB21+EK21+ET21 -> 0 | IP21: =CS21+EC21+EL21+EU21 -> 0.1 | IQ21: =CT21+ED21+EM21+EV21 -> 0 | IR21: =CU21+EE21+EN21+EW21 -> 0 | IS21: =CV21+EF21+EO21+EX21 -> 0 | IT21: =CW21+EG21+EP21+EY21 -> 2 | IU21: =CX21+EH21+EQ21+EZ21 -> 0.9 | IV21: 0 | IW21: 1
A22: 16 | B22: Melquiades Mendoza Madero | C22: Dibulla | D22: Larga La Vida | E22: 9.1 | F22: 15.2 | G22: =1250+450 -> 1700 | I22: 1250 | J22: 0 | O22: 0 | P22: 500 | Q22: 750 | V22: 703 | W22: 0 | Y22: 733 | AD22: 0 | AJ22: 733 | AK22: 2250 | AL22: 1146 | AQ22: 450 | AR22: 654 | AS22: 1146 | AY22: 1104 | AZ22: 120 | BA22: 0 | BG22: 60 | BH22: 0 | BN22: 60 | CG22: 0.2 | CJ22: 0.2 | CL22: 0 | CN22: 0 | EJ22: 2.1 | EK22: 0 | EL22: 0 | EQ22: 2.1 | IF22: =BX22+CG22+GB22+GK22+GT22 -> 0.2 | IG22: =BY22+CH22+GC22+GL22+GU22 -> 0 | IH22: =BZ22+CI22+GD22+GM22+GV22 -> 0 | II22: =CA22+CJ22+GE22+GN22+GW22 -> 0.2 | IJ22: =CB22+CK22+GF22+GO22+GX22 -> 0 | IK22: =CC22+CL22+GG22+GP22+GY22 -> 0 | IL22: =CD22+CM22+GH22+GQ22+GZ22 -> 0 | IM22: =CE22+CN22+GI22+GR22+HA22 -> 0 | IN22: =CQ22+EA22+EJ22+ES22 -> 2.1 | IO22: =CR22+EB22+EK22+ET22 -> 0 | IP22: =CS22+EC22+EL22+EU22 -> 0 | IQ22: =CT22+ED22+EM22+EV22 -> 0 | IR22: =CU22+EE22+EN22+EW22 -> 0 | IS22: =CV22+EF22+EO22+EX22 -> 0 | IT22: =CW22+EG22+EP22+EY22 -> 0 | IU22: =CX22+EH22+EQ22+EZ22 -> 2.1 | IV22: 1.6 | IW22: 1
A23: 17 | B23: Walter Antonio Hernández Fernández | C23: Dibulla | D23: Larga La Vida | E23: 12 | F23: 20 | G23: =750+800 -> 1550 | I23: 750 | O23: 0 | P23: 0 | Q23: 750 | V23: 0 | W23: 0 | AD23: 0 | AK23: 2805 | AL23: 0 | AN23: 170 | AO23: 1730 | AQ23: 451 | AR23: 454 | AS23: 0 | AU23: 170 | AV23: 1730 | AY23: 905 | AZ23: 175 | BA23: 0 | BF23: 120 | BG23: 0 | BH23: 0 | BM23: 120 | BN23: 0 | CG23: 2.6 | CJ23: 2.6 | CL23: 0 | CN23: 0 | EJ23: 2 | EK23: 0 | EL23: 0 | EP23: 1 | EQ23: 1 | IF23: =BX23+CG23+GB23+GK23+GT23 -> 2.6 | IG23: =BY23+CH23+GC23+GL23+GU23 -> 0 | IH23: =BZ23+CI23+GD23+GM23+GV23 -> 0 | II23: =CA23+CJ23+GE23+GN23+GW23 -> 2.6 | IJ23: =CB23+CK23+GF23+GO23+GX23 -> 0 | IK23: =CC23+CL23+GG23+GP23+GY23 -> 0 | IL23: =CD23+CM23+GH23+GQ23+GZ23 -> 0 | IM23: =CE23+CN23+GI23+GR23+HA23 -> 0 | IN23: =CQ23+EA23+EJ23+ES23 -> 2 | IO23: =CR23+EB23+EK23+ET23 -> 0 | IP23: =CS23+EC23+EL23+EU23 -> 0 | IQ23: =CT23+ED23+EM23+EV23 -> 0 | IR23: =CU23+EE23+EN23+EW23 -> 0 | IS23: =CV23+EF23+EO23+EX23 -> 0 | IT23: =CW23+EG23+EP23+EY23 -> 1 | IU23: =CX23+EH23+EQ23+EZ23 -> 1 | IV23: 2.5 | IW23: 1
A24: 18 | B24: Manuel Villareal Guevara | C24: Dibulla | D24: Larga La Vida | E24: 11.7 | F24: 19.5 | G24: =750+300 -> 1050 | I24: 750 | O24: 0 | Q24: 750 | V24: 0 | W24: 0 | AD24: 0 | AK24: 1934 | AL24: 1482 | AR24: 452 | AS24: 1482 | AY24: 452 | AZ24: 100 | BA24: 100 | BG24: 0 | BH24: 100 | BN24: 0 | CG24: 0.9 | CH24: 1 | CJ24: 0.9 | CL24: 0 | CN24: 0 | EJ24: 1 | EK24: 0.3 | EL24: 0.7 | EQ24: 0 | IF24: =BX24+CG24+GB24+GK24+GT24 -> 0.9 | IG24: =BY24+CH24+GC24+GL24+GU24 -> 1 | IH24: =BZ24+CI24+GD24+GM24+GV24 -> 0 | II24: =CA24+CJ24+GE24+GN24+GW24 -> 0.9 | IJ24: =CB24+CK24+GF24+GO24+GX24 -> 0 | IK24: =CC24+CL24+GG24+GP24+GY24 -> 0 | IL24: =CD24+CM24+GH24+GQ24+GZ24 -> 0 | IM24: =CE24+CN24+GI24+GR24+HA24 -> 0 | IN24: =CQ24+EA24+EJ24+ES24 -> 1 | IO24: =CR24+EB24+EK24+ET24 -> 0.3 | IP24: =CS24+EC24+EL24+EU24 -> 0.7 | IQ24: =CT24+ED24+EM24+EV24 -> 0 | IR24: =CU24+EE24+EN24+EW24 -> 0 | IS24: =CV24+EF24+EO24+EX24 -> 0 | IT24: =CW24+EG24+EP24+EY24 -> 0 | IU24: =CX24+EH24+EQ24+EZ24 -> 0 | IV24: 1.3 | IW24: 1
A25: 19 | B25: Jairo Fernández Conde | C25: Dibulla | D25: Larga La Vida | E25: 19.1 | F25: 8.4 | G25: =1500+300 -> 1800 | I25: 1500 | O25: 500 | P25: 1000 | V25: 0 | W25: 0 | AD25: 0 | AK25: 4754 | AL25: 2402 | AQ25: 433 | AR25: 1919 | AS25: 0 | AT25: 1910 | AY25: 2844 | AZ25: 113 | BA25: 113 | BF25: 20 | BG25: 20 | BH25: 113 | BM25: 20 | BN25: 20 | CG25: 3.3 | CJ25: 3.3 | CL25: 0 | CN25: 0 | EJ25: 2 | EK25: 0 | EL25: 1 | EM25: 1 | EP25: 0 | EQ25: 0 | IF25: =BX25+CG25+GB25+GK25+GT25 -> 3.3 | IG25: =BY25+CH25+GC25+GL25+GU25 -> 0 | IH25: =BZ25+CI25+GD25+GM25+GV25 -> 0 | II25: =CA25+CJ25+GE25+GN25+GW25 -> 3.3 | IJ25: =CB25+CK25+GF25+GO25+GX25 -> 0 | IK25: =CC25+CL25+GG25+GP25+GY25 -> 0 | IL25: =CD25+CM25+GH25+GQ25+GZ25 -> 0 | IM25: =CE25+CN25+GI25+GR25+HA25 -> 0 | IN25: =CQ25+EA25+EJ25+ES25 -> 2 | IO25: =CR25+EB25+EK25+ET25 -> 0 | IP25: =CS25+EC25+EL25+EU25 -> 1 | IQ25: =CT25+ED25+EM25+EV25 -> 1 | IR25: =CU25+EE25+EN25+EW25 -> 0 | IS25: =CV25+EF25+EO25+EX25 -> 0 | IT25: =CW25+EG25+EP25+EY25 -> 0 | IU25: =CX25+EH25+EQ25+EZ25 -> 0 | IV25: 0 | IW25: 1
A26: 20 | B26: Fani Leonor Gutiérrez Manjarrez | C26: Dibulla | D26: Larga La Vida | E26: 17 | F26: 28.3 | G26: =1500+600 -> 2100 | I26: 1500 | O26: 0 | P26: 500 | Q26: 1000 | V26: 0 | W26: 0 | AD26: 0 | AK26: 2932 | AL26: 1251 | AQ26: 288 | AR26: 1393 | AS26: 0 | AT26: 700 | AU26: 551 | AY26: 1681 | AZ26: 289 | BA26: 113 | BE26: 77 | BF26: 100 | BG26: 0 | BH26: 0 | BI26: 113 | BL26: 77 | BM26: 100 | BN26: 0 | CG26: 1.3 | CJ26: 1.3 | CL26: 0 | CN26: 0 | EJ26: 5.2 | EK26: 0 | EL26: 1 | EO26: 1 | EP26: 1 | EQ26: 2.2 | IF26: =BX26+CG26+GB26+GK26+GT26 -> 1.3 | IG26: =BY26+CH26+GC26+GL26+GU26 -> 0 | IH26: =BZ26+CI26+GD26+GM26+GV26 -> 0 | II26: =CA26+CJ26+GE26+GN26+GW26 -> 1.3 | IJ26: =CB26+CK26+GF26+GO26+GX26 -> 0 | IK26: =CC26+CL26+GG26+GP26+GY26 -> 0 | IL26: =CD26+CM26+GH26+GQ26+GZ26 -> 0 | IM26: =CE26+CN26+GI26+GR26+HA26 -> 0 | IN26: =CQ26+EA26+EJ26+ES26 -> 5.2 | IO26: =CR26+EB26+EK26+ET26 -> 0 | IP26: =CS26+EC26+EL26+EU26 -> 1 | IQ26: =CT26+ED26+EM26+EV26 -> 0 | IR26: =CU26+EE26+EN26+EW26 -> 0 | IS26: =CV26+EF26+EO26+EX26 -> 1 | IT26: =CW26+EG26+EP26+EY26 -> 1 | IU26: =CX26+EH26+EQ26+EZ26 -> 2.2 | IV26: 1.3 | IW26: 1
A27: 21 | B27: Matilde Durango Fernández | C27: Dibulla | D27: Larga La Vida | E27: 15.3 | F27: 8.4 | G27: =1500+300 -> 1800 | I27: 1500 | O27: 500 | P27: 1000 | V27: 0 | W27: 0 | AD27: 0 | AK27: 4433 | AL27: 1316 | AQ27: 167 | AR27: 2950 | AS27: 0 | AT27: 740 | AY27: 3693 | AZ27: 275 | BA27: 100 | BF27: 100 | BG27: 0 | BH27: 0 | BI27: 100 | BM27: 100 | BN27: 0 | CG27: 1.2 | CJ27: 1.2 | CL27: 0 | CN27: 0 | EJ27: 2 | EK27: 0.3 | EL27: 0.7 | EP27: 1 | EQ27: 0 | IF27: =BX27+CG27+GB27+GK27+GT27 -> 1.2 | IG27: =BY27+CH27+GC27+GL27+GU27 -> 0 | IH27: =BZ27+CI27+GD27+GM27+GV27 -> 0 | II27: =CA27+CJ27+GE27+GN27+GW27 -> 1.2 | IJ27: =CB27+CK27+GF27+GO27+GX27 -> 0 | IK27: =CC27+CL27+GG27+GP27+GY27 -> 0 | IL27: =CD27+CM27+GH27+GQ27+GZ27 -> 0 | IM27: =CE27+CN27+GI27+GR27+HA27 -> 0 | IN27: =CQ27+EA27+EJ27+ES27 -> 2 | IO27: =CR27+EB27+EK27+ET27 -> 0.3 | IP27: =CS27+EC27+EL27+EU27 -> 0.7 | IQ27: =CT27+ED27+EM27+EV27 -> 0 | IR27: =CU27+EE27+EN27+EW27 -> 0 | IS27: =CV27+EF27+EO27+EX27 -> 0 | IT27: =CW27+EG27+EP27+EY27 -> 1 | IU27: =CX27+EH27+EQ27+EZ27 -> 0 | IV27: 0 | IW27: 1
A28: 22 | B28: Yelene Rosio Serrano Ortiz | C28: Dibulla | D28: Larga La Vida | E28: 2 | F28: 0 | G28: 500 | I28: 0 | O28: 0 | V28: 703 | W28: 0 | X28: 703 | AD28: 0 | AF28: 200 | AJ28: 503 | AK28: 1684 | AL28: 1406 | AR28: 278 | AS28: 1406 | AY28: 278 | AZ28: 195 | BA28: 100 | BF28: 95 | BG28: 0 | BH28: 100 | BM28: 95 | BN28: 0 | CG28: 0.04 | CH28: 0.5 | CJ28: 0.04 | CL28: 0 | CN28: 0 | EJ28: 0.8 | EK28: 0.3 | EL28: 1 | EP28: 1 | EQ28: 0 | FT28: 1 | IF28: =BX28+CG28+GB28+GK28+GT28 -> 0.04 | IG28: =BY28+CH28+GC28+GL28+GU28 -> 0.5 | IH28: =BZ28+CI28+GD28+GM28+GV28 -> 0 | II28: =CA28+CJ28+GE28+GN28+GW28 -> 0.04 | IJ28: =CB28+CK28+GF28+GO28+GX28 -> 0 | IK28: =CC28+CL28+GG28+GP28+GY28 -> 0 | IL28: =CD28+CM28+GH28+GQ28+GZ28 -> 0 | IM28: =CE28+CN28+GI28+GR28+HA28 -> 0 | IN28: =CQ28+EA28+EJ28+ES28 -> 0.8 | IO28: =CR28+EB28+EK28+ET28 -> 0.3 | IP28: =CS28+EC28+EL28+EU28 -> 1 | IQ28: =CT28+ED28+EM28+EV28 -> 0 | IR28: =CU28+EE28+EN28+EW28 -> 0 | IS28: =CV28+EF28+EO28+EX28 -> 0 | IT28: =CW28+EG28+EP28+EY28 -> 1 | IU28: =CX28+EH28+EQ28+EZ28 -> 0 | IV28: 0 | IW28: 1
A29: 23 | B29: Esteban David Brito López | C29: Dibulla | D29: Larga La Vida | E29: 13.4 | F29: 25 | G29: =1500+600 -> 2100 | I29: 1500 | O29: 1500 | V29: 0 | W29: 0 | AD29: 0 | AK29: 2306 | AL29: 1325 | AR29: 981 | AS29: 1325 | AY29: 981 | AZ29: 350 | BA29: 275 | BF29: 95 | BG29: 0 | BH29: 275 | BM29: 95 | BN29: 0 | CG29: 1 | CH29: 1 | CL29: 0 | CN29: 0 | EJ29: 1.8 | EK29: 2 | EL29: 0 | EP29: 1 | EQ29: 0 | IF29: =BX29+CG29+GB29+GK29+GT29 -> 1 | IG29: =BY29+CH29+GC29+GL29+GU29 -> 1 | IH29: =BZ29+CI29+GD29+GM29+GV29 -> 0 | II29: =CA29+CJ29+GE29+GN29+GW29 -> 0 | IJ29: =CB29+CK29+GF29+GO29+GX29 -> 0 | IK29: =CC29+CL29+GG29+GP29+GY29 -> 0 | IL29: =CD29+CM29+GH29+GQ29+GZ29 -> 0 | IM29: =CE29+CN29+GI29+GR29+HA29 -> 0 | IN29: =CQ29+EA29+EJ29+ES29 -> 1.8 | IO29: =CR29+EB29+EK29+ET29 -> 2 | IP29: =CS29+EC29+EL29+EU29 -> 0 | IQ29: =CT29+ED29+EM29+EV29 -> 0 | IR29: =CU29+EE29+EN29+EW29 -> 0 | IS29: =CV29+EF29+EO29+EX29 -> 0 | IT29: =CW29+EG29+EP29+EY29 -> 1 | IU29: =CX29+EH29+EQ29+EZ29 -> 0 | IV29: 1.2 | IW29: 1
A30: 24 | B30: Aramendi De Jesús Móvil Montero | C30: Dibulla | D30: Larga La Vida | E30: 17.4 | F30: 0 | G30: 600 | I30: 0 | O30: 0 | V30: 703 | W30: 0 | X30: 703 | AD30: 0 | AF30: 0 | AG30: 535 | AJ30: 168 | AK30: 2624 | AL30: 0 | AN30: 452 | AP30: 2624 | AR30: 0 | AS30: 0 | AW30: 2624 | AY30: 452 | AZ30: 195 | BA30: 0 | BF30: 120 | BG30: 0 | BH30: 0 | BM30: 120 | BN30: 0 | CG30: 0.5 | CL30: 0.5 | CN30: 0 | EJ30: 2 | EK30: 0 | EL30: 0.3 | EO30: 0.6 | EP30: 1 | EQ30: 0.1 | IF30: =BX30+CG30+GB30+GK30+GT30 -> 0.5 | IG30: =BY30+CH30+GC30+GL30+GU30 -> 0 | IH30: =BZ30+CI30+GD30+GM30+GV30 -> 0 | II30: =CA30+CJ30+GE30+GN30+GW30 -> 0 | IJ30: =CB30+CK30+GF30+GO30+GX30 -> 0 | IK30: =CC30+CL30+GG30+GP30+GY30 -> 0.5 | IL30: =CD30+CM30+GH30+GQ30+GZ30 -> 0 | IM30: =CE30+CN30+GI30+GR30+HA30 -> 0 | IN30: =CQ30+EA30+EJ30+ES30 -> 2 | IO30: =CR30+EB30+EK30+ET30 -> 0 | IP30: =CS30+EC30+EL30+EU30 -> 0.3 | IQ30: =CT30+ED30+EM30+EV30 -> 0 | IR30: =CU30+EE30+EN30+EW30 -> 0 | IS30: =CV30+EF30+EO30+EX30 -> 0.6 | IT30: =CW30+EG30+EP30+EY30 -> 1 | IU30: =CX30+EH30+EQ30+EZ30 -> 0.1 | IV30: 3.7 | IW30: 1
A31: 25 | B31: Deisi Movil Montero | C31: Dibulla | D31: Larga La Vida | E31: 12.2 | F31: 0 | G31: 0 | I31: 0 | O31: 0 | V31: 703 | W31: 0 | X31: 703 | AD31: 0 | AF31: 200 | AG31: 160 | AJ31: 343 | AK31: 3016 | AL31: 416 | AP31: 2600 | AR31: 0 | AS31: 416 | AY31: 2600 | AZ31: 195 | BA31: 0 | BF31: 120 | BG31: 0 | BH31: 0 | BM31: 120 | BN31: 0 | CG31: 0.4 | CJ31: 0.4 | CL31: 0 | CN31: 0 | EJ31: 1.8 | EK31: 0 | EL31: 0.3 | EM31: 0.7 | EP31: 0.8 | EQ31: 0 | IF31: =BX31+CG31+GB31+GK31+GT31 -> 0.4 | IG31: =BY31+CH31+GC31+GL31+GU31 -> 0 | IH31: =BZ31+CI31+GD31+GM31+GV31 -> 0 | II31: =CA31+CJ31+GE31+GN31+GW31 -> 0.4 | IJ31: =CB31+CK31+GF31+GO31+GX31 -> 0 | IK31: =CC31+CL31+GG31+GP31+GY31 -> 0 | IL31: =CD31+CM31+GH31+GQ31+GZ31 -> 0 | IM31: =CE31+CN31+GI31+GR31+HA31 -> 0 | IN31: =CQ31+EA31+EJ31+ES31 -> 1.8 | IO31: =CR31+EB31+EK31+ET31 -> 0 | IP31: =CS31+EC31+EL31+EU31 -> 0.3 | IQ31: =CT31+ED31+EM31+EV31 -> 0.7 | IR31: =CU31+EE31+EN31+EW31 -> 0 | IS31: =CV31+EF31+EO31+EX31 -> 0 | IT31: =CW31+EG31+EP31+EY31 -> 0.8 | IU31: =CX31+EH31+EQ31+EZ31 -> 0 | IV31: 1.6 | IW31: 1
A32: 26 | B32: Wilmer Yeimeser Quinto Miranda | C32: Dibulla | D32: Larga La Vida | E32: 5.3 | F32: 29 | G32: 4264 | I32: 3514 | O32: 0 | P32: 150 | Q32: 3364 | V32: 1055 | W32: 0 | AD32: 0 | AK32: 2055 | AL32: 654 | AQ32: 1401 | AR32: 0 | AS32: 500 | AU32: 154 | AY32: 1401 | AZ32: 0 | BA32: 0 | BF32: 0 | BG32: 0 | BH32: 0 | BN32: 0 | CG32: 0.5 | CJ32: 0.5 | CL32: 0 | CN32: 0 | EJ32: 1.4 | EK32: 0.3 | EL32: 1 | EQ32: 0.1 | IF32: =BX32+CG32+GB32+GK32+GT32 -> 0.5 | IG32: =BY32+CH32+GC32+GL32+GU32 -> 0 | IH32: =BZ32+CI32+GD32+GM32+GV32 -> 0 | II32: =CA32+CJ32+GE32+GN32+GW32 -> 0.5 | IJ32: =CB32+CK32+GF32+GO32+GX32 -> 0 | IK32: =CC32+CL32+GG32+GP32+GY32 -> 0 | IL32: =CD32+CM32+GH32+GQ32+GZ32 -> 0 | IM32: =CE32+CN32+GI32+GR32+HA32 -> 0 | IN32: =CQ32+EA32+EJ32+ES32 -> 1.4 | IO32: =CR32+EB32+EK32+ET32 -> 0.3 | IP32: =CS32+EC32+EL32+EU32 -> 1 | IQ32: =CT32+ED32+EM32+EV32 -> 0 | IR32: =CU32+EE32+EN32+EW32 -> 0 | IS32: =CV32+EF32+EO32+EX32 -> 0 | IT32: =CW32+EG32+EP32+EY32 -> 0 | IU32: =CX32+EH32+EQ32+EZ32 -> 0.1 | IV32: 0 | IW32: 1
A33: 27 | B33: Oscar Emilio Barros Peñaloza | C33: Dibulla | D33: Larga La Vida | E33: 9.4 | F33: 4.2 | G33: =250+225 -> 475 | I33: 250 | O33: 250 | V33: 0 | W33: 0 | AD33: 0 | AK33: 904 | AL33: 354 | AR33: 550 | AS33: 354 | AY33: 550 | AZ33: 125 | BA33: 100 | BF33: 20 | BG33: 0 | BH33: 100 | BM33: 20 | BN33: 0 | CG33: 1 | CH33: 1 | CL33: 0 | CN33: 0 | CQ33: 3.7 | CR33: 0 | CW33: 2 | CX33: 1.7 | EJ33: 1 | EK33: 0 | EL33: 1 | EQ33: 0 | FT33: 1 | IF33: =BX33+CG33+GB33+GK33+GT33 -> 1 | IG33: =BY33+CH33+GC33+GL33+GU33 -> 1 | IH33: =BZ33+CI33+GD33+GM33+GV33 -> 0 | II33: =CA33+CJ33+GE33+GN33+GW33 -> 0 | IJ33: =CB33+CK33+GF33+GO33+GX33 -> 0 | IK33: =CC33+CL33+GG33+GP33+GY33 -> 0 | IL33: =CD33+CM33+GH33+GQ33+GZ33 -> 0 | IM33: =CE33+CN33+GI33+GR33+HA33 -> 0 | IN33: =CQ33+EA33+EJ33+ES33 -> 4.7 | IO33: =CR33+EB33+EK33+ET33 -> 0 | IP33: =CS33+EC33+EL33+EU33 -> 1 | IQ33: =CT33+ED33+EM33+EV33 -> 0 | IR33: =CU33+EE33+EN33+EW33 -> 0 | IS33: =CV33+EF33+EO33+EX33 -> 0 | IT33: =CW33+EG33+EP33+EY33 -> 2 | IU33: =CX33+EH33+EQ33+EZ33 -> 1.7 | IV33: 1.5 | IW33: 1
A34: 28 | B34: Esther María Valiente Meriño | C34: Dibulla | D34: Larga La Vida | E34: 8 | F34: 8.4 | G34: =500+250 -> 750 | I34: 500 | P34: 500 | V34: 0 | W34: 0 | AD34: 0 | AK34: 1083 | AL34: 733 | AR34: 350 | AS34: 0 | AT34: 570 | AU34: 163 | AY34: 350 | AZ34: 0 | BA34: 195 | BG34: 0 | BH34: 0 | BM34: 95 | BN34: 100 | CG34: 0.2 | CH34: 0 | CJ34: 0.2 | CL34: 0 | CN34: 0 | EJ34: 2 | EK34: 0 | EL34: 1 | EQ34: 1 | IF34: =BX34+CG34+GB34+GK34+GT34 -> 0.2 | IG34: =BY34+CH34+GC34+GL34+GU34 -> 0 | IH34: =BZ34+CI34+GD34+GM34+GV34 -> 0 | II34: =CA34+CJ34+GE34+GN34+GW34 -> 0.2 | IJ34: =CB34+CK34+GF34+GO34+GX34 -> 0 | IK34: =CC34+CL34+GG34+GP34+GY34 -> 0 | IL34: =CD34+CM34+GH34+GQ34+GZ34 -> 0 | IM34: =CE34+CN34+GI34+GR34+HA34 -> 0 | IN34: =CQ34+EA34+EJ34+ES34 -> 2 | IO34: =CR34+EB34+EK34+ET34 -> 0 | IP34: =CS34+EC34+EL34+EU34 -> 1 | IQ34: =CT34+ED34+EM34+EV34 -> 0 | IR34: =CU34+EE34+EN34+EW34 -> 0 | IS34: =CV34+EF34+EO34+EX34 -> 0 | IT34: =CW34+EG34+EP34+EY34 -> 0 | IU34: =CX34+EH34+EQ34+EZ34 -> 1 | IV34: 1.3 | IW34: 1
A35: 29 | B35: Adalfredo Serrano Zapata | C35: Dibulla | D35: Larga La Vida | E35: 12.6 | F35: 0 | G35: 325 | I35: 0 | O35: 0 | V35: 703 | W35: 703 | AD35: 0 | AE35: 500 | AF35: 203 | AK35: 2872 | AL35: 1894 | AN35: 192 | AQ35: 786 | AR35: 0 | AS35: 1894 | AY35: 978 | AZ35: 16 | BA35: 16 | BF35: 50 | BG35: 0 | BH35: 16 | BM35: 50 | BN35: 0 | CG35: 1.5 | CH35: 1.5 | CJ35: 1.5 | CL35: 0 | CN35: 0 | EJ35: 2 | EK35: 1 | EL35: 1 | EP35: 0.5 | EQ35: 0 | IF35: =BX35+CG35+GB35+GK35+GT35 -> 1.5 | IG35: =BY35+CH35+GC35+GL35+GU35 -> 1.5 | IH35: =BZ35+CI35+GD35+GM35+GV35 -> 0 | II35: =CA35+CJ35+GE35+GN35+GW35 -> 1.5 | IJ35: =CB35+CK35+GF35+GO35+GX35 -> 0 | IK35: =CC35+CL35+GG35+GP35+GY35 -> 0 | IL35: =CD35+CM35+GH35+GQ35+GZ35 -> 0 | IM35: =CE35+CN35+GI35+GR35+HA35 -> 0 | IN35: =CQ35+EA35+EJ35+ES35 -> 2 | IO35: =CR35+EB35+EK35+ET35 -> 1 | IP35: =CS35+EC35+EL35+EU35 -> 1 | IQ35: =CT35+ED35+EM35+EV35 -> 0 | IR35: =CU35+EE35+EN35+EW35 -> 0 | IS35: =CV35+EF35+EO35+EX35 -> 0 | IT35: =CW35+EG35+EP35+EY35 -> 0.5 | IU35: =CX35+EH35+EQ35+EZ35 -> 0 | IV35: 0 | IW35: 1
A36: 30 | B36: Jairo Navarro Ramírez | C36: Dibulla | D36: Larga La Vida | E36: 13.3 | F36: 0 | G36: 361 | I36: 0 | J36: 111 | O36: 0 | Q36: 111 | V36: 0 | W36: 0 | AD36: 0 | AK36: 511 | AL36: 0 | AN36: 15 | AP36: 61 | AR36: 435 | AS36: 0 | AW36: 61 | AY36: 450 | AZ36: 173 | BA36: 103 | BF36: 105 | BG36: 0 | BH36: 103 | BM36: 105 | BN36: 0 | CG36: 1 | CL36: 0.5 | CM36: 0.5 | CN36: 0 | CQ36: 5 | CR36: 0 | CU36: 0 | CV36: 0 | CW36: 2.5 | CX36: 2.5 | EJ36: 3.5 | EK36: 0.3 | EL36: 0.7 | EP36: 1 | EQ36: 1.5 | FT36: 2 | IF36: =BX36+CG36+GB36+GK36+GT36 -> 1 | IG36: =BY36+CH36+GC36+GL36+GU36 -> 0 | IH36: =BZ36+CI36+GD36+GM36+GV36 -> 0 | II36: =CA36+CJ36+GE36+GN36+GW36 -> 0 | IJ36: =CB36+CK36+GF36+GO36+GX36 -> 0 | IK36: =CC36+CL36+GG36+GP36+GY36 -> 0.5 | IL36: =CD36+CM36+GH36+GQ36+GZ36 -> 0.5 | IM36: =CE36+CN36+GI36+GR36+HA36 -> 0 | IN36: =CQ36+EA36+EJ36+ES36 -> 8.5 | IO36: =CR36+EB36+EK36+ET36 -> 0.3 | IP36: =CS36+EC36+EL36+EU36 -> 0.7 | IQ36: =CT36+ED36+EM36+EV36 -> 0 | IR36: =CU36+EE36+EN36+EW36 -> 0 | IS36: =CV36+EF36+EO36+EX36 -> 0 | IT36: =CW36+EG36+EP36+EY36 -> 3.5 | IU36: =CX36+EH36+EQ36+EZ36 -> 4 | IV36: 0 | IW36: 1
A37: 31 | B37: William Rafael Cotes Cúrvelo | C37: Dibulla | D37: Larga La Vida | E37: 8.3 | F37: 0 | G37: 300 | I37: 0 | O37: 0 | V37: 703 | W37: 0 | Y37: 703 | AD37: 0 | AJ37: 703 | AK37: 2624 | AL37: 1244 | AQ37: 131 | AR37: 1249 | AS37: 0 | AU37: 1244 | AY37: 1380 | AZ37: 176 | BA37: 0 | BG37: 100 | BH37: 0 | BN37: 100 | CG37: 0.2 | CJ37: 0.2 | CL37: 0 | CN37: 0 | EJ37: 1 | EK37: 0 | EL37: 0 | EQ37: 1 | IF37: =BX37+CG37+GB37+GK37+GT37 -> 0.2 | IG37: =BY37+CH37+GC37+GL37+GU37 -> 0 | IH37: =BZ37+CI37+GD37+GM37+GV37 -> 0 | II37: =CA37+CJ37+GE37+GN37+GW37 -> 0.2 | IJ37: =CB37+CK37+GF37+GO37+GX37 -> 0 | IK37: =CC37+CL37+GG37+GP37+GY37 -> 0 | IL37: =CD37+CM37+GH37+GQ37+GZ37 -> 0 | IM37: =CE37+CN37+GI37+GR37+HA37 -> 0 | IN37: =CQ37+EA37+EJ37+ES37 -> 1 | IO37: =CR37+EB37+EK37+ET37 -> 0 | IP37: =CS37+EC37+EL37+EU37 -> 0 | IQ37: =CT37+ED37+EM37+EV37 -> 0 | IR37: =CU37+EE37+EN37+EW37 -> 0 | IS37: =CV37+EF37+EO37+EX37 -> 0 | IT37: =CW37+EG37+EP37+EY37 -> 0 | IU37: =CX37+EH37+EQ37+EZ37 -> 1 | IV37: 2.1 | IW37: 1
A38: 32 | B38: Álvaro Zambrano Gutiérrez | C38: El Doncello | D38: Birmania | E38: 18.4 | G38: 100 | I38: 100 | J38: 0 | P38: 100 | Q38: 0 | V38: 100 | W38: 0 | Y38: 100 | AD38: 0 | AF38: 0 | AH38: 100 | AK38: 340 | AL38: 340 | AM38: 0 | AN38: 0 | AP38: 0 | AS38: 160 | AU38: 0 | AW38: 180 | AZ38: 21 | BB38: 21 | BC38: 0 | BI38: 21 | BJ38: 0 | CQ38: 5.6 | CR38: 2 | CS38: 2 | CT38: 0 | CU38: 0 | CV38: 1.6 | DI38: 3 | DJ38: 12 | DK38: 5 | DL38: 2 | DM38: 0 | DN38: 0 | DO38: 5 | EJ38: 1 | EK38: 0 | EL38: 1 | EM38: 0 | FS38: =SUM(FL38+FM38+FN38+FO38+FP38)-FK38 -> 0 | GB38: 1.8 | GC38: 0 | GD38: 0.5 | GE38: 1.3 | HL38: 1 | HM38: 0 | HN38: 0 | HO38: 1 | IF38: =BX38+CG38+GB38+GK38+GT38 -> 1.8 | IG38: =BY38+CH38+GC38+GL38+GU38 -> 0 | IH38: =BZ38+CI38+GD38+GM38+GV38 -> 0.5 | II38: =CA38+CJ38+GE38+GN38+GW38 -> 1.3 | IJ38: =CB38+CK38+GF38+GO38+GX38 -> 0 | IK38: =CC38+CL38+GG38+GP38+GY38 -> 0 | IL38: =CD38+CM38+GH38+GQ38+GZ38 -> 0 | IM38: =CE38+CN38+GI38+GR38+HA38 -> 0 | IN38: =CQ38+EA38+EJ38+ES38 -> 6.6 | IO38: =CR38+EB38+EK38+ET38 -> 2 | IP38: =CS38+EC38+EL38+EU38 -> 3 | IQ38: =CT38+ED38+EM38+EV38 -> 0 | IR38: =CU38+EE38+EN38+EW38 -> 0 | IS38: =CV38+EF38+EO38+EX38 -> 1.6 | IT38: =CW38+EG38+EP38+EY38 -> 0 | IU38: =CX38+EH38+EQ38+EZ38 -> 0 | IV38: 1.8 | IW38: 1
A39: 33 | B39: Leandro Cantillo Gutiérrez | C39: El Doncello | D39: Birmania | E39: 95.9 | G39: 100 | I39: 100 | J39: 0 | P39: 100 | Q39: 0 | V39: 0 | W39: 0 | Y39: 0 | AD39: 0 | AK39: 175 | AL39: 175 | AM39: 0 | AN39: 0 | AP39: 0 | AS39: 75 | AU39: 3 | AW39: 97 | AZ39: 12 | BB39: 12 | BC39: 0 | BI39: 12 | BJ39: 0 | BK39: 0 | BO39: 1 | BR39: 0 | BT39: 1 | BX39: 0.1 | BY39: 0 | BZ39: 0 | CA39: 0 | CC39: 0.1 | CQ39: 19.9 | CR39: 0 | CS39: 0 | CT39: 10 | CU39: 0 | CV39: 9.9 | DK39: 0 | EJ39: 0.2 | EK39: 0.2 | EL39: 0 | EM39: 0 | FS39: =SUM(FL39+FM39+FN39+FO39+FP39)-FK39 -> 0 | IF39: =BX39+CG39+GB39+GK39+GT39 -> 0.1 | IG39: =BY39+CH39+GC39+GL39+GU39 -> 0 | IH39: =BZ39+CI39+GD39+GM39+GV39 -> 0 | II39: =CA39+CJ39+GE39+GN39+GW39 -> 0 | IJ39: =CB39+CK39+GF39+GO39+GX39 -> 0 | IK39: =CC39+CL39+GG39+GP39+GY39 -> 0.1 | IL39: =CD39+CM39+GH39+GQ39+GZ39 -> 0 | IM39: =CE39+CN39+GI39+GR39+HA39 -> 0 | IN39: =CQ39+EA39+EJ39+ES39 -> 20.1 | IO39: =CR39+EB39+EK39+ET39 -> 0.2 | IP39: =CS39+EC39+EL39+EU39 -> 0 | IQ39: =CT39+ED39+EM39+EV39 -> 10 | IR39: =CU39+EE39+EN39+EW39 -> 0 | IS39: =CV39+EF39+EO39+EX39 -> 9.9 | IT39: =CW39+EG39+EP39+EY39 -> 0 | IU39: =CX39+EH39+EQ39+EZ39 -> 0 | IV39: 7.2 | IW39: 1
A40: 34 | B40: Nidia Vanegas Trujillo | C40: El Doncello | D40: Birmania | E40: 11.3 | G40: 200 | I40: 200 | J40: 0 | P40: 200 | Q40: 0 | V40: 0 | W40: 0 | Y40: 0 | AD40: 0 | AF40: 0 | AK40: 60 | AL40: 60 | AM40: 0 | AN40: 0 | AP40: 0 | AS40: 60 | AU40: 0 | AZ40: 25 | BB40: 25 | BC40: 0 | BI40: 25 | BJ40: 0 | CV40: 0 | EJ40: 1 | EK40: 1 | EL40: 0 | EM40: 0 | FS40: =SUM(FL40+FM40+FN40+FO40+FP40)-FK40 -> 0 | HU40: 1 | HV40: 0 | HW40: 0 | HX40: 1 | IF40: =BX40+CG40+GB40+GK40+GT40 -> 0 | IG40: =BY40+CH40+GC40+GL40+GU40 -> 0 | IH40: =BZ40+CI40+GD40+GM40+GV40 -> 0 | II40: =CA40+CJ40+GE40+GN40+GW40 -> 0 | IJ40: =CB40+CK40+GF40+GO40+GX40 -> 0 | IK40: =CC40+CL40+GG40+GP40+GY40 -> 0 | IL40: =CD40+CM40+GH40+GQ40+GZ40 -> 0 | IM40: =CE40+CN40+GI40+GR40+HA40 -> 0 | IN40: =CQ40+EA40+EJ40+ES40 -> 1 | IO40: =CR40+EB40+EK40+ET40 -> 1 | IP40: =CS40+EC40+EL40+EU40 -> 0 | IQ40: =CT40+ED40+EM40+EV40 -> 0 | IR40: =CU40+EE40+EN40+EW40 -> 0 | IS40: =CV40+EF40+EO40+EX40 -> 0 | IT40: =CW40+EG40+EP40+EY40 -> 0 | IU40: =CX40+EH40+EQ40+EZ40 -> 0 | IV40: 4 | IW40: 1
A41: 35 | B41: Rosalba Ortiz | C41: El Doncello | D41: Birmania | E41: 19.9 | G41: 0 | I41: 0 | P41: 0 | V41: 0 | W41: 0 | Y41: 0 | AD41: 0 | AK41: 50 | AL41: 50 | AM41: 0 | AN41: 0 | AP41: 0 | AS41: 30 | AU41: 20 | AZ41: 30 | BB41: 30 | BC41: 0 | BI41: 30 | CQ41: 4.3 | CS41: 4.3 | CT41: 0 | CU41: 0 | CV41: 0 | EJ41: 0.5 | EK41: 0.5 | EL41: 0 | EM41: 0 | FS41: =SUM(FL41+FM41+FN41+FO41+FP41)-FK41 -> 0 | HL41: 1 | HM41: 0 | HN41: 0 | HO41: 0 | HQ41: 1 | IF41: =BX41+CG41+GB41+GK41+GT41 -> 0 | IG41: =BY41+CH41+GC41+GL41+GU41 -> 0 | IH41: =BZ41+CI41+GD41+GM41+GV41 -> 0 | II41: =CA41+CJ41+GE41+GN41+GW41 -> 0 | IJ41: =CB41+CK41+GF41+GO41+GX41 -> 0 | IK41: =CC41+CL41+GG41+GP41+GY41 -> 0 | IL41: =CD41+CM41+GH41+GQ41+GZ41 -> 0 | IM41: =CE41+CN41+GI41+GR41+HA41 -> 0 | IN41: =CQ41+EA41+EJ41+ES41 -> 4.8 | IO41: =CR41+EB41+EK41+ET41 -> 0.5 | IP41: =CS41+EC41+EL41+EU41 -> 4.3 | IQ41: =CT41+ED41+EM41+EV41 -> 0 | IR41: =CU41+EE41+EN41+EW41 -> 0 | IS41: =CV41+EF41+EO41+EX41 -> 0 | IT41: =CW41+EG41+EP41+EY41 -> 0 | IU41: =CX41+EH41+EQ41+EZ41 -> 0 | IV41: 8.4 | IW41: 1
A42: 36 | B42: Antonio Londoño | C42: El Doncello | D42: Birmania | E42: 23.3 | G42: 300 | I42: 300 | J42: 0 | P42: 300 | Q42: 0 | V42: 0 | W42: 0 | Y42: 0 | AD42: 0 | AK42: 35 | AL42: 35 | AM42: 0 | AN42: 0 | AP42: 0 | AS42: 0 | AU42: 35 | AZ42: 25 | BB42: 25 | BC42: 0 | BI42: 25 | BJ42: 0 | CQ42: 8.5 | CS42: 0 | CT42: 3.6 | CU42: 2 | CV42: 2.9 | DI42: 4 | DJ42: 12 | DM42: 5 | DN42: 4 | DO42: 3 | EJ42: 0.5 | EK42: 0.5 | EL42: 0 | EM42: 0 | FS42: =SUM(FL42+FM42+FN42+FO42+FP42)-FK42 -> 0 | HL42: 1 | HM42: 0 | HN42: 0 | HO42: 0 | HQ42: 1 | IF42: =BX42+CG42+GB42+GK42+GT42 -> 0 | IG42: =BY42+CH42+GC42+GL42+GU42 -> 0 | IH42: =BZ42+CI42+GD42+GM42+GV42 -> 0 | II42: =CA42+CJ42+GE42+GN42+GW42 -> 0 | IJ42: =CB42+CK42+GF42+GO42+GX42 -> 0 | IK42: =CC42+CL42+GG42+GP42+GY42 -> 0 | IL42: =CD42+CM42+GH42+GQ42+GZ42 -> 0 | IM42: =CE42+CN42+GI42+GR42+HA42 -> 0 | IN42: =CQ42+EA42+EJ42+ES42 -> 9 | IO42: =CR42+EB42+EK42+ET42 -> 0.5 | IP42: =CS42+EC42+EL42+EU42 -> 0 | IQ42: =CT42+ED42+EM42+EV42 -> 3.6 | IR42: =CU42+EE42+EN42+EW42 -> 2 | IS42: =CV42+EF42+EO42+EX42 -> 2.9 | IT42: =CW42+EG42+EP42+EY42 -> 0 | IU42: =CX42+EH42+EQ42+EZ42 -> 0 | IV42: 4.5 | IW42: 1
A43: 37 | B43: Aparicio Franco | C43: El Doncello | D43: Birmania | E43: 1.5 | G43: 200 | I43: 200 | J43: 0 | P43: 200 | Q43: 0 | V43: 0 | W43: 0 | Y43: 0 | AD43: 0 | AK43: 60 | AL43: 60 | AM43: 0 | AN43: 0 | AP43: 0 | AS43: 60 | AU43: 0 | AZ43: 0 | BB43: 0 | BC43: 0 | BI43: 0 | BJ43: 0 | EJ43: 1.1 | EK43: 0.5 | EL43: 0.6 | EM43: 0 | FS43: =SUM(FL43+FM43+FN43+FO43+FP43)-FK43 -> 0 | HL43: 1 | HM43: 0 | HN43: 0 | HO43: 0 | HQ43: 1 | IF43: =BX43+CG43+GB43+GK43+GT43 -> 0 | IG43: =BY43+CH43+GC43+GL43+GU43 -> 0 | IH43: =BZ43+CI43+GD43+GM43+GV43 -> 0 | II43: =CA43+CJ43+GE43+GN43+GW43 -> 0 | IJ43: =CB43+CK43+GF43+GO43+GX43 -> 0 | IK43: =CC43+CL43+GG43+GP43+GY43 -> 0 | IL43: =CD43+CM43+GH43+GQ43+GZ43 -> 0 | IM43: =CE43+CN43+GI43+GR43+HA43 -> 0 | IN43: =CQ43+EA43+EJ43+ES43 -> 1.1 | IO43: =CR43+EB43+EK43+ET43 -> 0.5 | IP43: =CS43+EC43+EL43+EU43 -> 0.6 | IQ43: =CT43+ED43+EM43+EV43 -> 0 | IR43: =CU43+EE43+EN43+EW43 -> 0 | IS43: =CV43+EF43+EO43+EX43 -> 0 | IT43: =CW43+EG43+EP43+EY43 -> 0 | IU43: =CX43+EH43+EQ43+EZ43 -> 0 | IV43: 0 | IW43: 1
...

Sheet Consolidado
A1: Colinos (piña y plátano) | D1: Árboles de Cacao | G1: Forestales (viveros comunitarios) | J1: Frutales | N1: Área de nacimiento aislar (ha) | P1: Área de fuente hídrica a aislar | S1: Sistemas silvopastoriles | U1: Implementación de SAF | W1: Enriquecimiento de SAF | Z1: Cercas vivas (metros) | AB1: División de Potrero (# Potreros) | AE1: Acueducto Ganadero (Metros) | AG1: Adecuación de Biodigestor | AJ1: Corredor de Conectividad | AL1: Enriquecimiento Rastrojo | AN1: Enriquecimiento de Bosque | AP1: Restauración de área degradada | AS1: Colmenas | AU1: Huertas sin cubierta | AW1: Huerta bajo cubierta | AY1: Fortalecimiento Gallinas Criollas
A2: Meta | B2: Entregados | C2: Sembrados | D2: Meta | E2: Entregados | F2: Sembrados | G2: Meta | H2: Entregados | I2: Sembrados | J2: Meta | K2: Entregados | L2: Sembrados | N2: Meta | O2: Avance | P2: Meta | Q2: Avance | S2: Meta | T2: Avance | U2: Meta | V2: Avance | W2: Meta | X2: Avance | Z2: Meta | AA2: Avance | AB2: # Potreros Iniciales | AC2: Meta # Potreros | AD2: Avance | AE2: Meta | AF2: Avance | AG2: Meta | AH2: Avance | AJ2: Meta | AK2: Avance | AL2: Meta | AM2: Avance | AN2: Meta | AO2: Avance | AP2: Meta | AQ2: Avance | AS2: Meta | AT2: Avance | AU2: Meta | AV2: Avance | AW2: Meta | AX2: Avance | AY2: Meta | AZ2: Avance
A3: =T4_2025!G129 -> 58645 | B3: =T4_2025!H129+T4_2025!I129+T4_2025!J129+T4_2025!K129+T4_2025!L129+T4_2025!M129+T4_2025!N129 -> 48645 | C3: =T4_2025!O129+T4_2025!P129+T4_2025!Q129+T4_2025!R129+T4_2025!S129+T4_2025!T129+T4_2025!U129 -> 48645 | D3: =T4_2025!V129 -> 11810 | E3: =T4_2025!W129+T4_2025!X129+T4_2025!Y129+T4_2025!Z129+T4_2025!AA129+T4_2025!AB129+T4_2025!AC129 -> 11418 | F3: =T4_2025!AD129+T4_2025!AE129+T4_2025!AF129+T4_2025!AG129+T4_2025!AH129+T4_2025!AI129+T4_2025!AJ129 -> 11418 | G3: =T4_2025!AK129 -> 144833 | H3: =T4_2025!AL129+T4_2025!AM129+T4_2025!AN129+T4_2025!AO129+T4_2025!AP129+T4_2025!AQ129+T4_2025!AR129 -> 137795 | I3: =T4_2025!AS129+T4_2025!AT129+T4_2025!AU129+T4_2025!AV129+T4_2025!AW129+T4_2025!AX129+T4_2025!AY129 -> 137795 | J3: =T4_2025!AZ129 -> 8889 | K3: =T4_2025!BA129+T4_2025!BB129+T4_2025!BC129+T4_2025!BD129+T4_2025!BE129+T4_2025!BF129+T4_2025!BG129 -> 8054 | L3: =T4_2025!BH129+T4_2025!BI129+T4_2025!BJ129+T4_2025!BK129+T4_2025!BL129+T4_2025!BM129+T4_2025!BN129 -> 8099 | N3: =T4_2025!BX129 -> 4.08 | O3: =T4_2025!BY129+T4_2025!BZ129+T4_2025!CA129+T4_2025!CB129+T4_2025!CC129+T4_2025!CD129+T4_2025!CE129 -> 4.075 | P3: =T4_2025!CG129 -> 56.55 | Q3: =T4_2025!CH129+T4_2025!CI129+T4_2025!CJ129+T4_2025!CK129+T4_2025!CL129+T4_2025!CM129+T4_2025!CN129 -> 65.1 | S3: =T4_2025!CQ129 -> 509.9 | T3: =T4_2025!CR129+T4_2025!CS129+T4_2025!CT129+T4_2025!CU129+T4_2025!CV129+T4_2025!CW129+T4_2025!CX129 -> 541.45 | U3: =T4_2025!EJ129 -> 146.86 | V3: =T4_2025!EK129+T4_2025!EL129+T4_2025!EM129+T4_2025!EN129+T4_2025!EO129+T4_2025!EP129+T4_2025!EQ129 -> 158.31 | W3: =T4_2025!EA129 -> 4.5 | X3: =T4_2025!EB129+T4_2025!EC129+T4_2025!ED129+T4_2025!EE129+T4_2025!EF129+T4_2025!EG129+T4_2025!EH129 -> 4.5 | Z3: =T4_2025!CZ129 -> 28688 | AA3: =T4_2025!DA129+T4_2025!DB129+T4_2025!DC129+T4_2025!DD129+T4_2025!DE129+T4_2025!DF129+T4_2025!DG129 -> 29388 | AB3: =T4_2025!DI129 -> 224 | AC3: =T4_2025!DJ129 -> 643 | AD3: =T4_2025!DK129+T4_2025!DL129+T4_2025!DM129+T4_2025!DN129+T4_2025!DO129+T4_2025!DP129+T4_2025!DQ129 -> 672 | AE3: =T4_2025!FK129 -> 22200 | AF3: =T4_2025!FL129+T4_2025!FM129+T4_2025!FN129+T4_2025!FO129+T4_2025!FP129+T4_2025!FQ129+T4_2025!FR129 -> 22400 | AG3: =T4_2025!FB129 -> 3 | AH3: =T4_2025!FC129+T4_2025!FD129+T4_2025!FE129+T4_2025!FF129+T4_2025!FG129+T4_2025!FH129+T4_2025!FI129 -> 8 | AJ3: =T4_2025!ES129 -> 5.49 | AK3: =T4_2025!ET129+T4_2025!EU129+T4_2025!EV129+T4_2025!EW129+T4_2025!EX129+T4_2025!EY129+T4_2025!EZ129 -> 5.4904 | AL3: =T4_2025!GB129 -> 3.8 | AM3: =T4_2025!GC129+T4_2025!GD129+T4_2025!GE129+T4_2025!GF129+T4_2025!GG129+T4_2025!GH129+T4_2025!GI129 -> 3.8 | AN3: =T4_2025!GK129 -> 1 | AO3: =T4_2025!GL129+T4_2025!GM129+T4_2025!GN129+T4_2025!GO129+T4_2025!GP129+T4_2025!GQ129+T4_2025!GR129 -> 1 | AP3: =T4_2025!HC129 -> 3 | AQ3: =T4_2025!GU129+T4_2025!GV129+T4_2025!GW129+T4_2025!GX129+T4_2025!GY129+T4_2025!GZ129+T4_2025!HA129 -> 3.21 | AS3: 0 | AT3: =T4_2025!FT129+T4_2025!FU129+T4_2025!FV129+T4_2025!FW129+T4_2025!FX129+T4_2025!FY129+T4_2025!FZ129 -> 95 | AU3: =[2]T3_2024!DO129 -> 3 | AV3: =T4_2025!HD129+T4_2025!HE129+T4_2025!HF129+T4_2025!HG129+T4_2025!HH129+T4_2025!HI129+T4_2025!HJ129 -> 4 | AW3: =T4_2025!HL129 -> 29 | AX3: =T4_2025!HM129+T4_2025!HN129+T4_2025!HO129+T4_2025!HP129+T4_2025!HQ129+T4_2025!HR129+T4_2025!HS129 -> 29 | AY3: =[2]T3_2024!DX129 -> 7 | AZ3: =T4_2025!HV129+T4_2025!HX129+T4_2025!HY129+T4_2025!HZ129+T4_2025!IA129+T4_2025!IB129 -> 7
