Workbook

Sheet General
A1: PROYECTO: ConBosque | B1: FFEM
A2: CUADRO: | B2: CONSTRUCCIÓN PLAN DE INVERSIONES
A3: VEREDA / : La Bamba, El Rosal y Soncelejo | E3: VEREDA LOS ÁNGELES
A4: Descripcion Producto | B4: Cantidad | C4: Precio Unit | D4: Precio Total | E4: Rubiel Perez
A5: Aceite Cadenoil x Galón | B5: =SUM(E5:E5) -> 0 | C5: 70000 | D5: =B5*C5 -> 0
A6: Aislador puntilla Bolsa *100 Marca Lhaura | B6: =SUM(E6:E6) -> 5 | C6: 25300 | D6: =B6*C6 -> 126500 | E6: =Rubiel_Perez!H15 -> 5
A7: Aislador Pera bolsa*25 Marca Lhaura | B7: =SUM(E7:E7) -> 4 | C7: 35600 | D7: =B7*C7 -> 142400 | E7: =Rubiel_Perez!H12 -> 4
A8: Alambre aislador rollo*50 | B8: =SUM(E8:E8) -> 2 | C8: 50000 | D8: =B8*C8 -> 100000 | E8: =Rubiel_Perez!H14 -> 2
A9: Alambre de cerca Calibre 14 x Rollo x 1000 Metros | B9: =SUM(E9:E9) -> 10 | C9: 270000 | D9: =B9*C9 -> 2700000 | E9: =Rubiel_Perez!H11 -> 10
A10: Alambre de cerca Calibre 12 x Rollo x 1000 Metros | B10: =SUM(E10:E10) -> 0 | C10: 270000 | D10: =B10*C10 -> 0
A11: Alambre de Cobre Calibre 12 x Metro | B11: =SUM(E11:E11) -> 0 | C11: 3500 | D11: =B11*C11 -> 0
A12: Alambre de Cobre Calibre 14 x Metro | B12: =SUM(E12:E12) -> 50 | C12: 3500 | D12: =B12*C12 -> 175000 | E12: =Rubiel_Perez!H21 -> 50
A13: Alambre de pua Calibre 12,5 Rollo x 330Metro Proalco | B13: =SUM(E13:E13) -> 0 | C13: 350000 | D13: =B13*C13 -> 0
A14: Alambre de Pua calibre 14 X 500 mts Proalco | B14: =SUM(E14:E14) -> 0 | C14: 350000 | D14: =B14*C14 -> 0
A15: Alambre de Pua calibre 16.5 Rollo x 400 Metros Proalco | B15: =SUM(E15:E15) -> 0 | C15: 350000 | D15: =B15*C15 -> 0
A16: Alambre de pua calibre calibre 16 x 100 metros | B16: =SUM(E16:E16) -> 0 | C16: 123000 | D16: =B16*C16 -> 0
A17: Alambre Aluminio Cal 6 X Mtrs | B17: =SUM(E17:E17) -> 0 | C17: 350000 | D17: =B17*C17 -> 0
A18: Alambre Dulce Calibre 16 x Kilo | B18: =SUM(E18:E18) -> 0 | C18: 3500 | D18: =B18*C18 -> 0
A19: Alambre Negro para amarre x kilo | B19: =SUM(E19:E19) -> 0 | C19: 10000 | D19: =B19*C19 -> 0
A20: Alicate Universal de 8" | B20: =SUM(E20:E20) -> 0 | C20: 350000 | D20: =B20*C20 -> 0
A21: Alicate Diablo x Unidad | B21: =SUM(E21:E21) -> 0 | C21: 350000 | D21: =B21*C21 -> 0
A22: Amarres x 100 para zinc | B22: =SUM(E22:E22) -> 0 | C22: 350000 | D22: =B22*C22 -> 0
A23: Araña para regar Alambre | B23: =SUM(E23:E23) -> 0 | C23: 350000 | D23: =B23*C23 -> 0
A24: Azadón con cabo B/H | B24: =SUM(E24:E24) -> 0 | C24: 350000 | D24: =B24*C24 -> 0
A25: Aro Plateo para Guadaña | B25: =SUM(E25:E25) -> 0 | C25: 350000 | D25: =B25*C25 -> 0
A26: Adaptador PVC Hembra de ½" | B26: =SUM(E26:E26) -> 4 | C26: 2500 | D26: =B26*C26 -> 10000 | E26: =Rubiel_Perez!H53 -> 4
A27: Adaptador PVC Hembra de ¾" | B27: =SUM(E27:E27) -> 0 | C27: 2500 | D27: =B27*C27 -> 0
A28: Adaptador PVC Hembra de 1" | B28: =SUM(E28:E28) -> 0 | C28: 3000 | D28: =B28*C28 -> 0
A29: Adaptador PVC Macho de ½" | B29: =SUM(E29:E29) -> 4 | C29: 2500 | D29: =B29*C29 -> 10000 | E29: =Rubiel_Perez!H54 -> 4
A30: Adaptador PVC Macho de ¾" | B30: =SUM(E30:E30) -> 0 | C30: 2500 | D30: =B30*C30 -> 0
A31: Adaptador PVC Macho de 1" | B31: =SUM(E31:E31) -> 0 | C31: 3000 | D31: =B31*C31 -> 0
A32: Adaptador PVC Macho de 1 1/4" | B32: =SUM(E32:E32) -> 1 | C32: 4000 | D32: =B32*C32 -> 4000 | E32: =Rubiel_Perez!H56 -> 1
A33: Adaptador PVC Macho de 1 1/2" | B33: =SUM(E33:E33) -> 1 | C33: 5000 | D33: =B33*C33 -> 5000 | E33: =Rubiel_Perez!H55 -> 1
A34: Bandeja Semillero Plástica x Unidad | B34: =SUM(E34:E34) -> 0 | C34: 9800 | D34: =B34*C34 -> 0
A35: Barreton con cabo | B35: =SUM(E35:E35) -> 0 | C35: 40000 | D35: =B35*C35 -> 0
A36: Bateria seca 12/100 MAGNA | B36: =SUM(E36:E36) -> 1 | C36: 1000000 | D36: =B36*C36 -> 1000000 | E36: =Rubiel_Perez!H17 -> 1
A37: Bateria solar grande green point GELL (150 AMP) | B37: =SUM(E37:E37) -> 0 | C37: 1250000 | D37: =B37*C37 -> 0
A38: Bateria solar grande magna GELL (150 AMP) | B38: =SUM(E38:E38) -> 0 | C38: 1350000 | D38: =B38*C38 -> 0
A39: Bateria solar mediana (120 AMP) | B39: =SUM(E39:E39) -> 0 | C39: 1120494 | D39: =B39*C39 -> 0
A40: Bateria Solar 55 AMP | B40: =SUM(E40:E40) -> 0 | C40: 600000 | D40: =B40*C40 -> 0
...

Sheet Rubiel_Perez
K6: Abejas
B7: ACTIVIDADES DE INVERSION FAMILIA: _Rubiel Perez
B8: ACTIVIDAD # 1. Implementación de 5,3 hectáreas de sistema silvopastoril de 2 potreros se sacan 10 potreros de 0,5 hectareas
B9: SUB ACTIVIDAD | C9: APORTE DE LA FAMILIA | G9: APORTE DEL PROYECTO
C10: ARTICULO | D10: CANTIDAD | E10: VALOR UNI | F10: VALOR TOTAL | G10: ARTICULO | H10: CANTIDAD | I10: VALOR UNI | J10: VALOR TOTAL
C11: Estantillos y mano de obra | D11: 200 | E11: 25000 | F11: =D11*E11 -> 5000000 | G11: Alambre de cerca Calibre 14 x Rollo x 1000 Metros Puma | H11: 10 | I11: 270000 | J11: =H11*I11 -> 2700000
G12: Aislador Pera bolsa*25 Marca Súper Fox | H12: 4 | I12: 35000 | J12: =H12*I12 -> 140000
F13: =D13*E13 -> 0 | G13: Tensor pequeño 500 metros punto rojo | H13: 70 | I13: 5000 | J13: =H13*I13 -> 350000
F14: =D14*E14 -> 0 | G14: Alambre aislador rollo*50 Súper Fox | H14: 2 | I14: 60000 | J14: =H14*I14 -> 120000
G15: Aisldor Puntila bolsa x 100 unidades | H15: 5 | I15: 38000 | J15: =H15*I15 -> 190000 | L15: 151
G16: Puntilla de 3" | H16: 5 | I16: 6000 | J16: =H16*I16 -> 30000
G17: Bateria seca 12/100 MAGNA | H17: 1 | I17: 1000000 | J17: =H17*I17 -> 1000000
G18: Impulsor 50 km 12V Superfox | H18: 1 | I18: 380000 | J18: =H18*I18 -> 380000
G19: Cuchilla doble tiro Super fox | H19: 1 | I19: 30000 | J19: =H19*I19 -> 30000
G20: Desviador de rayo superfox | H20: 1 | I20: 33000 | J20: =H20*I20 -> 33000
G21: Alambre de Cobre Calibre 14 x Metro | H21: 50 | I21: 3500 | J21: =H21*I21 -> 175000
G22: Regulador 20 AMP/12V | H22: 1 | I22: 130000 | J22: =H22*I22 -> 130000
B24: SUBTOTAL | F24: =SUM(F11:F23) -> 5000000 | G24: SUBTOTAL | J24: =SUM(J11:J23) -> 5278000
B26: ACTIVIDAD # 2. Implementación de 800 metros de acueducto ganadero
B27: SUB ACTIVIDAD | C27: APORTE DE LA FAMILIA | G27: APORTE DEL PROYECTO
C28: ARTICULO | D28: CANTIDAD | E28: VALOR UNI | F28: VALOR TOTAL | G28: ARTICULO | H28: CANTIDAD | I28: VALOR UNI | J28: VALOR TOTAL
B29: Adecuación de acueducto ganader | C29: Torre para tanque | D29: 1 | E29: 2000000 | F29: =D29*E29 -> 2000000 | G29: Tanque Plástico 2000 Litros Alto con tapa x Unidad Proco | H29: 1 | I29: 1088000 | J29: =H29*I29 -> 1088000
C30: Mano de obra | D30: 10 | E30: 90000 | F30: =D30*E30 -> 900000 | G30: Tubo PVC 1 pulgada x 6m presion | H30: 1 | I30: 35000 | J30: =H30*I30 -> 35000
G31: Tubo PVC 1 1/2" pulgada x 6m presion | H31: 2 | I31: 45000 | J31: =H31*I31 -> 90000
C32: Árboles de carbon | D32: 100 | E32: 3000 | F32: =D32*E32 -> 300000 | G32: T Lisa de PVC de 1" | H32: 1 | I32: 1333 | J32: =H32*I32 -> 1333
C33: Aljibe | D33: 1 | E33: 300000 | F33: =D33*E33 -> 300000 | G33: Llave de paso de PVC 1" | H33: 2 | I33: 32000 | J33: =H33*I33 -> 64000
G34: Llave de paso de PVC 1 1/2" | H34: 1 | I34: 40000 | J34: =H34*I34 -> 40000
F35: =D35*E35 -> 0 | G35: Unión universal de 1" | H35: 1 | I35: 11000 | J35: =H35*I35 -> 11000
G36: Unión universal de 1 1/2"" | H36: 2 | I36: 13000 | J36: =H36*I36 -> 26000
G37: Unión PVC de 1 1/2" | H37: 3 | I37: 5900 | J37: =H37*I37 -> 17700
F38: =D38*E38 -> 0 | G38: Codo PVC de 1" | H38: 2 | I38: 2000 | J38: =H38*I38 -> 4000
G39: Codo PVC de 1 1/2" | H39: 5 | I39: 5000 | J39: =H39*I39 -> 25000
F40: =D40*E40 -> 0 | G40: Reducción de PVC de 1" a 3/4" | H40: 2 | I40: 1333 | J40: =H40*I40 -> 2666
F41: =D41*E41 -> 0 | G41: Inserto 3/4" de manguera a tubo x unidad | H41: 10 | I41: 4000 | J41: =H41*I41 -> 40000
G42: T para manguera de 3/4" | H42: 3 | I42: 3000 | J42: =H42*I42 -> 9000
G43: Inserto 1/2" de manguera a tubo x unidad | H43: 6 | I43: 2000 | J43: =H43*I43 -> 12000
G44: Inserto de PVC de 1" ½" | H44: 3
F45: =D45*E45 -> 0 | G45: Manguera PP 3/4x100 C40 Peletizada Rollo x 100 Metros | H45: 4 | I45: 146667 | J45: =H45*I45 -> 586668
G46: Manguera PP 1 1/2"x100 C40 Peletizada Rollo x 100 Metros | H46: 2 | I46: 200000 | J46: =H46*I46 -> 400000
F47: =D47*E47 -> 0 | G47: T 3/4" salida rosca presion x unidad | H47: 5 | I47: 2000 | J47: =H47*I47 -> 10000
...

Sheet Jairo_Marin
B7: ACTIVIDADES DE INVERSION FAMILIA: _Jairo Marin
B8: ACTIVIDAD # 1. Implementación de 9,6 hectáreas de sistema silvopastoril de 2 potreros se sacan 10 potreros de 0,5 hectareas
B9: SUB ACTIVIDAD | C9: APORTE DE LA FAMILIA | G9: APORTE DEL PROYECTO
C10: ARTICULO | D10: CANTIDAD | E10: VALOR UNI | F10: VALOR TOTAL | G10: ARTICULO | H10: CANTIDAD | I10: VALOR UNI | J10: VALOR TOTAL
C11: Estantillos y mano de obra | D11: 400 | E11: 25000 | F11: =D11*E11 -> 10000000 | G11: Alambre de cerca Calibre 14 x Rollo x 1000 Metros Puma | H11: 15 | I11: 270000 | J11: =H11*I11 -> 4050000
G12: Aislador Pera bolsa*25 Marca Súper Fox | H12: 4 | I12: 35000 | J12: =H12*I12 -> 140000
F13: =D13*E13 -> 0 | G13: Tensor pequeño 500 metros punto rojo | H13: 70 | I13: 5000 | J13: =H13*I13 -> 350000 | K13: 1600
F14: =D14*E14 -> 0 | G14: Alambre aislador rollo*50 Súper Fox | H14: 2 | I14: 60000 | J14: =H14*I14 -> 120000
G15: Aisldor Puntila bolsa x 100 unidades | H15: 5 | I15: 38000 | J15: =H15*I15 -> 190000 | L15: 151
G16: Puntilla de 3" | H16: 5 | I16: 6000 | J16: =H16*I16 -> 30000
J17: =H17*I17 -> 0
B18: SUBTOTAL | F18: =SUM(F11:F17) -> 10000000 | G18: SUBTOTAL | J18: =SUM(J11:J17) -> 4880000
B20: ACTIVIDAD # 2. Implementación de 800 metros de acueducto ganadero
B21: SUB ACTIVIDAD | C21: APORTE DE LA FAMILIA | G21: APORTE DEL PROYECTO
C22: ARTICULO | D22: CANTIDAD | E22: VALOR UNI | F22: VALOR TOTAL | G22: ARTICULO | H22: CANTIDAD | I22: VALOR UNI | J22: VALOR TOTAL
B23: Adecuación de acueducto ganader | C23: Torre para tanque | D23: 1 | E23: 2000000 | F23: =D23*E23 -> 2000000 | G23: Tanque Plástico 2000 Litros Alto con tapa x Unidad Proco | H23: 1 | I23: 1088000 | J23: =H23*I23 -> 1088000
C24: Mano de obra | D24: 10 | E24: 90000 | F24: =D24*E24 -> 900000 | G24: Tubo PVC 1 pulgada x 6m presion | H24: 1 | I24: 35000 | J24: =H24*I24 -> 35000
G25: Tubo PVC 1 1/2" pulgada x 6m presion | H25: 2 | I25: 45000 | J25: =H25*I25 -> 90000
C26: Arboles frutales: guanabana blanca, borojo, caimo, citricos | D26: 50
C27: Árboles de carbon | D27: 50 | E27: 3000 | F27: =D27*E27 -> 150000 | G27: T Lisa de PVC de 1" | H27: 1 | I27: 1333 | J27: =H27*I27 -> 1333
C28: Aljibe | D28: 1 | E28: 300000 | F28: =D28*E28 -> 300000 | G28: Llave de paso de PVC 1" | H28: 2 | I28: 32000 | J28: =H28*I28 -> 64000
G29: Llave de paso de PVC 1 1/2" | H29: 1 | I29: 40000 | J29: =H29*I29 -> 40000
F30: =D30*E30 -> 0 | G30: Unión universal de 1" | H30: 1 | I30: 11000 | J30: =H30*I30 -> 11000
G31: Unión universal de 1 1/2"" | H31: 2 | I31: 13000 | J31: =H31*I31 -> 26000
G32: Unión PVC de 1 1/2" | H32: 3 | I32: 5900 | J32: =H32*I32 -> 17700
F33: =D33*E33 -> 0 | G33: Codo PVC de 1" | H33: 2 | I33: 2000 | J33: =H33*I33 -> 4000
G34: Codo PVC de 1 1/2" | H34: 5 | I34: 5000 | J34: =H34*I34 -> 25000
F35: =D35*E35 -> 0 | G35: Reducción de PVC de 1" a 3/4" | H35: 2 | I35: 1333 | J35: =H35*I35 -> 2666
F36: =D36*E36 -> 0 | G36: Inserto 3/4" de manguera a tubo x unidad | H36: 10 | I36: 4000 | J36: =H36*I36 -> 40000
G37: T para manguera de 3/4" | H37: 3 | I37: 3000 | J37: =H37*I37 -> 9000
G38: Inserto 1/2" de manguera a tubo x unidad | H38: 6 | I38: 2000 | J38: =H38*I38 -> 12000
G39: Inserto de PVC de 1" ½" | H39: 3
F40: =D40*E40 -> 0 | G40: Manguera PP 3/4x100 C40 Peletizada Rollo x 100 Metros | H40: 4 | I40: 146667 | J40: =H40*I40 -> 586668
G41: Manguera PP 1 1/2"x100 C40 Peletizada Rollo x 100 Metros | H41: 1 | I41: 200000 | J41: =H41*I41 -> 200000
F42: =D42*E42 -> 0 | G42: T 3/4" salida rosca presion x unidad | H42: 5 | I42: 2000 | J42: =H42*I42 -> 10000
F43: =D43*E43 -> 0 | G43: Codo PVC de 3/4" con rosca | H43: 2 | I43: 1333 | J43: =H43*I43 -> 2666
F44: =D44*E44 -> 0 | G44: Hidrantes de 3/4" | H44: 5 | I44: 38000 | J44: =H44*I44 -> 190000
F45: =D45*E45 -> 0 | G45: unión de manguera 3/4" | H45: 5 | I45: 2700 | J45: =H45*I45 -> 13500
G46: Unión de manguera 1 1/2" | H46: 1 | I46: 2700 | J46: =H46*I46 -> 2700
F47: =D47*E47 -> 0 | G47: bayoneta de 1/2" | H47: 2 | I47: 16000 | J47: =H47*I47 -> 32000 | L47: 130
...

Sheet Liliana_Gaviria
B7: ACTIVIDADES DE INVERSION FAMILIA: _Liliana Gaviria
B8: ACTIVIDAD # 1. Implementación de 10 hectáreas de sistema silvopastoril de 4 potreros se sacan 20 potreros de 0,5 hectareas
B9: SUB ACTIVIDAD | C9: APORTE DE LA FAMILIA | G9: APORTE DEL PROYECTO
C10: ARTICULO | D10: CANTIDAD | E10: VALOR UNI | F10: VALOR TOTAL | G10: ARTICULO | H10: CANTIDAD | I10: VALOR UNI | J10: VALOR TOTAL
C11: Estantillos y mano de obra | D11: 500 | E11: 30000 | F11: =D11*E11 -> 15000000 | G11: Alambre de cerca Calibre 14 x Rollo x 1000 Metros Puma | H11: 10 | I11: 270000 | J11: =H11*I11 -> 2700000
G12: Aislador Pera bolsa*25 Marca Súper Fox | H12: 4 | I12: 35000 | J12: =H12*I12 -> 140000
F13: =D13*E13 -> 0 | G13: Tensor pequeño 500 metros punto rojo | H13: 100 | I13: 5000 | J13: =H13*I13 -> 500000 | K13: 1600
F14: =D14*E14 -> 0 | G14: Alambre aislador rollo*50 Súper Fox | H14: 2 | I14: 60000 | J14: =H14*I14 -> 120000
G15: Aisldor Puntila bolsa x 100 unidades | H15: 12 | I15: 38000 | J15: =H15*I15 -> 456000 | L15: 151
G16: Puntilla de 3" | H16: 12 | I16: 6000 | J16: =H16*I16 -> 72000
J17: =H17*I17 -> 0
B18: SUBTOTAL | F18: =SUM(F11:F17) -> 15000000 | G18: SUBTOTAL | J18: =SUM(J11:J17) -> 3988000
B20: ACTIVIDAD # 2. Implementación de 800 metros de acueducto ganadero
B21: SUB ACTIVIDAD | C21: APORTE DE LA FAMILIA | G21: APORTE DEL PROYECTO
C22: ARTICULO | D22: CANTIDAD | E22: VALOR UNI | F22: VALOR TOTAL | G22: ARTICULO | H22: CANTIDAD | I22: VALOR UNI | J22: VALOR TOTAL
B23: Adecuación de acueducto ganader | C23: Torre para tanque | D23: 1 | E23: 2000000 | F23: =D23*E23 -> 2000000 | G23: Tanque Plástico 2000 Litros Alto con tapa x Unidad Proco | H23: 1 | I23: 1088000 | J23: =H23*I23 -> 1088000
C24: Mano de obra | D24: 15 | E24: 90000 | F24: =D24*E24 -> 1350000 | G24: Tubo PVC 1 pulgada x 6m presion | H24: 1 | I24: 35000 | J24: =H24*I24 -> 35000
G25: Tubo PVC 1 1/2" pulgada x 6m presion | H25: 2 | I25: 45000 | J25: =H25*I25 -> 90000
C26: Arboles frutales: guanabana blanca, borojo, caimo, citricos | D26: 50
C27: Árboles de ceiba | D27: 10 | E27: 3000 | F27: =D27*E27 -> 30000 | G27: T Lisa de PVC de 1" | H27: 1 | I27: 1333 | J27: =H27*I27 -> 1333
C28: Aljibe | D28: 1 | E28: 300000 | F28: =D28*E28 -> 300000 | G28: Llave de paso de PVC 1" | H28: 2 | I28: 32000 | J28: =H28*I28 -> 64000
G29: Llave de paso de PVC 1 1/2" | H29: 1 | I29: 40000 | J29: =H29*I29 -> 40000
F30: =D30*E30 -> 0 | G30: Unión universal de 1" | H30: 1 | I30: 11000 | J30: =H30*I30 -> 11000
G31: Unión universal de 1 1/2"" | H31: 2 | I31: 13000 | J31: =H31*I31 -> 26000
G32: Unión PVC de 1 1/2" | H32: 3 | I32: 5900 | J32: =H32*I32 -> 17700
F33: =D33*E33 -> 0 | G33: Codo PVC de 1" | H33: 2 | I33: 2000 | J33: =H33*I33 -> 4000
G34: Codo PVC de 1 1/2" | H34: 5 | I34: 5000 | J34: =H34*I34 -> 25000
F35: =D35*E35 -> 0 | G35: Reducción de PVC de 1" a 3/4" | H35: 2 | I35: 1333 | J35: =H35*I35 -> 2666
F36: =D36*E36 -> 0 | G36: Inserto 3/4" de manguera a tubo x unidad | H36: 10 | I36: 4000 | J36: =H36*I36 -> 40000
G37: T para manguera de 3/4" | H37: 3 | I37: 3000 | J37: =H37*I37 -> 9000
G38: Inserto 1/2" de manguera a tubo x unidad | H38: 6 | I38: 2000 | J38: =H38*I38 -> 12000
G39: Inserto de PVC de 1" ½" | H39: 3
F40: =D40*E40 -> 0 | G40: Manguera PP 3/4x100 C40 Peletizada Rollo x 100 Metros | H40: 4 | I40: 146667 | J40: =H40*I40 -> 586668
G41: Manguera PP 1 1/2"x100 C40 Peletizada Rollo x 100 Metros | H41: 2 | I41: 200000 | J41: =H41*I41 -> 400000
F42: =D42*E42 -> 0 | G42: T 3/4" salida rosca presion x unidad | H42: 5 | I42: 2000 | J42: =H42*I42 -> 10000
F43: =D43*E43 -> 0 | G43: Codo PVC de 3/4" con rosca | H43: 2 | I43: 1333 | J43: =H43*I43 -> 2666
F44: =D44*E44 -> 0 | G44: Hidrantes de 3/4" | H44: 5 | I44: 38000 | J44: =H44*I44 -> 190000
F45: =D45*E45 -> 0 | G45: unión de manguera 3/4" | H45: 5 | I45: 2700 | J45: =H45*I45 -> 13500
G46: Unión de manguera 1 1/2" | H46: 1 | I46: 2700 | J46: =H46*I46 -> 2700
F47: =D47*E47 -> 0 | G47: bayoneta de 1/2" | H47: 2 | I47: 16000 | J47: =H47*I47 -> 32000 | L47: 130
...

Sheet NIdia_Motta
B7: ACTIVIDADES DE INVERSION FAMILIA: _Nidia Motta | K7: Abejas
B8: ACTIVIDAD # 1. Implementación de 9,8 hectáreas de sistema silvopastoril de 5 potreros se sacan 20 potreros de 0,5 hectareas
B9: SUB ACTIVIDAD | C9: APORTE DE LA FAMILIA | G9: APORTE DEL PROYECTO
C10: ARTICULO | D10: CANTIDAD | E10: VALOR UNI | F10: VALOR TOTAL | G10: ARTICULO | H10: CANTIDAD | I10: VALOR UNI | J10: VALOR TOTAL
C11: Estantillos y mano de obra | D11: 300 | E11: 30000 | F11: =D11*E11 -> 9000000 | G11: Alambre de cerca Calibre 14 x Rollo x 1000 Metros Puma | H11: 10 | I11: 270000 | J11: =H11*I11 -> 2700000 | K11: 1300 | L11: Más alambre para corredor
G12: Aislador Pera bolsa*25 Marca Súper Fox | H12: 4 | I12: 35000 | J12: =H12*I12 -> 140000
F13: =D13*E13 -> 0 | G13: Tensor pequeño 500 metros punto rojo | H13: 70 | I13: 5000 | J13: =H13*I13 -> 350000 | K13: =K11*5 -> 6500
F14: =D14*E14 -> 0 | G14: Alambre aislador rollo*50 Súper Fox | H14: 2 | I14: 60000 | J14: =H14*I14 -> 120000
G15: Aisldor Puntila bolsa x 100 unidades | H15: 12 | I15: 38000 | J15: =H15*I15 -> 456000 | K15: 483 | L15: 151
G16: Puntilla de 3" | H16: 12 | I16: 6000 | J16: =H16*I16 -> 72000 | K16: 331
G17: =General!A40 -> Bateria Solar 55 AMP | H17: 1 | I17: 600000 | J17: =H17*I17 -> 600000
J18: =H18*I18 -> 0
J19: =H19*I19 -> 0
J20: =H20*I20 -> 0 | K20: =120*4 -> 480
B21: SUBTOTAL | F21: =SUM(F11:F20) -> 9000000 | G21: SUBTOTAL | J21: =SUM(J11:J20) -> 4438000 | M21: =K11/8 -> 162.5
B23: ACTIVIDAD # 2. Implementación de 800 metros de acueducto ganadero
B24: SUB ACTIVIDAD | C24: APORTE DE LA FAMILIA | G24: APORTE DEL PROYECTO
C25: ARTICULO | D25: CANTIDAD | E25: VALOR UNI | F25: VALOR TOTAL | G25: ARTICULO | H25: CANTIDAD | I25: VALOR UNI | J25: VALOR TOTAL
B26: Adecuación de acueducto ganader | C26: Torre para tanque | D26: 1 | E26: 2000000 | F26: =D26*E26 -> 2000000 | G26: Tanque Plástico 2000 Litros Alto con tapa x Unidad Proco | H26: 1 | I26: 1088000 | J26: =H26*I26 -> 1088000
C27: Mano de obra | D27: 15 | E27: 90000 | F27: =D27*E27 -> 1350000 | G27: Tubo PVC 1 pulgada x 6m presion | H27: 1 | I27: 35000 | J27: =H27*I27 -> 35000
G28: Tubo PVC 1 1/2" pulgada x 6m presion | H28: 2 | I28: 45000 | J28: =H28*I28 -> 90000
C29: Arboles frutales: guanabana blanca, borojo, caimo, citricos | D29: 50
C30: Árboles de ceiba | D30: 10 | E30: 3000 | F30: =D30*E30 -> 30000 | G30: T Lisa de PVC de 1" | H30: 1 | I30: 1333 | J30: =H30*I30 -> 1333
C31: Aljibe | D31: 1 | E31: 300000 | F31: =D31*E31 -> 300000 | G31: Llave de paso de PVC 1" | H31: 2 | I31: 32000 | J31: =H31*I31 -> 64000
G32: Llave de paso de PVC 1 1/2" | H32: 1 | I32: 40000 | J32: =H32*I32 -> 40000
F33: =D33*E33 -> 0 | G33: Unión universal de 1" | H33: 1 | I33: 11000 | J33: =H33*I33 -> 11000
G34: Unión universal de 1 1/2"" | H34: 2 | I34: 13000 | J34: =H34*I34 -> 26000
G35: Unión PVC de 1 1/2" | H35: 3 | I35: 5900 | J35: =H35*I35 -> 17700
F36: =D36*E36 -> 0 | G36: Codo PVC de 1" | H36: 2 | I36: 2000 | J36: =H36*I36 -> 4000
G37: Codo PVC de 1 1/2" | H37: 5 | I37: 5000 | J37: =H37*I37 -> 25000
F38: =D38*E38 -> 0 | G38: Reducción de PVC de 1" a 3/4" | H38: 2 | I38: 1333 | J38: =H38*I38 -> 2666
F39: =D39*E39 -> 0 | G39: Inserto 3/4" de manguera a tubo x unidad | H39: 10 | I39: 4000 | J39: =H39*I39 -> 40000
G40: T para manguera de 3/4" | H40: 3 | I40: 3000 | J40: =H40*I40 -> 9000
G41: Inserto 1/2" de manguera a tubo x unidad | H41: 6 | I41: 2000 | J41: =H41*I41 -> 12000
G42: Inserto de PVC de 1" ½" | H42: 3
F43: =D43*E43 -> 0 | G43: Manguera PP 3/4x100 C40 Peletizada Rollo x 100 Metros | H43: 4 | I43: 146667 | J43: =H43*I43 -> 586668
G44: Manguera PP 1 1/2"x100 C40 Peletizada Rollo x 100 Metros | H44: 2 | I44: 200000 | J44: =H44*I44 -> 400000
F45: =D45*E45 -> 0 | G45: T 3/4" salida rosca presion x unidad | H45: 5 | I45: 2000 | J45: =H45*I45 -> 10000
F46: =D46*E46 -> 0 | G46: Codo PVC de 3/4" con rosca | H46: 2 | I46: 1333 | J46: =H46*I46 -> 2666
F47: =D47*E47 -> 0 | G47: Hidrantes de 3/4" | H47: 5 | I47: 38000 | J47: =H47*I47 -> 190000
...

Sheet Mauricio_Asencio
B7: ACTIVIDADES DE INVERSION FAMILIA: _Mauricio Asencio
B8: ACTIVIDAD # 1. Implementación de 26 hectáreas de sistema silvopastoril de 8 potreros se sacan 26 potreros de 1 hectareas
B9: SUB ACTIVIDAD | C9: APORTE DE LA FAMILIA | G9: APORTE DEL PROYECTO
C10: ARTICULO | D10: CANTIDAD | E10: VALOR UNI | F10: VALOR TOTAL | G10: ARTICULO | H10: CANTIDAD | I10: VALOR UNI | J10: VALOR TOTAL
C11: Estantillos y mano de obra | D11: 450 | E11: 30000 | F11: =D11*E11 -> 13500000 | G11: Alambre de cerca Calibre 14 x Rollo x 1000 Metros Puma | H11: 12 | I11: 230000 | J11: =H11*I11 -> 2760000 | K11: 2231 | L11: Más alambre para corredor | O11: =K11/7 -> 318.71429
G12: Aislador Pera bolsa*25 Marca Súper Fox | H12: 6 | I12: 35000 | J12: =H12*I12 -> 210000
F13: =D13*E13 -> 0 | G13: Tensor pequeño 500 metros punto rojo | H13: 80 | I13: 5000 | J13: =H13*I13 -> 400000 | N13: =K11*5 -> 11155
F14: =D14*E14 -> 0 | G14: Alambre aislador rollo*50 Súper Fox | H14: 2 | I14: 60000 | J14: =H14*I14 -> 120000 | L14: 221
G15: Aisldor Puntila bolsa x 100 unidades | H15: 14 | I15: 38000 | J15: =H15*I15 -> 532000 | L15: 192
G16: Puntilla de 3" | H16: 14 | I16: 6000 | J16: =H16*I16 -> 84000 | L16: 110
G17: =General!A40 -> Bateria Solar 55 AMP | H17: 1 | I17: 600000 | J17: =H17*I17 -> 600000 | L17: 100
G18: Panel solar de 55-60 AMP | H18: 1 | I18: 219000 | J18: =H18*I18 -> 219000 | L18: 393
G19: Regulador 10 AMP/12V | H19: 1 | I19: 110000 | J19: =H19*I19 -> 110000 | L19: 181
G20: Impulsor 50 km 12V Superfox | H20: 1 | I20: 450000 | J20: =H20*I20 -> 450000 | L20: 188
B21: SUBTOTAL | F21: =SUM(F11:F20) -> 13500000 | G21: SUBTOTAL | J21: =SUM(J11:J20) -> 5485000 | L21: 140
L22: 133
B23: ACTIVIDAD # 2. Implementación de 1000 metros de acueducto ganadero | L23: 130
B24: SUB ACTIVIDAD | C24: APORTE DE LA FAMILIA | G24: APORTE DEL PROYECTO | L24: 120
C25: ARTICULO | D25: CANTIDAD | E25: VALOR UNI | F25: VALOR TOTAL | G25: ARTICULO | H25: CANTIDAD | I25: VALOR UNI | J25: VALOR TOTAL | L25: 153
B26: Adecuación de acueducto ganader | C26: Torre para tanque | D26: 1 | E26: 2000000 | F26: =D26*E26 -> 2000000 | G26: Tanque Plástico 2000 Litros Alto con tapa x Unidad Proco | H26: 1 | I26: 1088000 | J26: =H26*I26 -> 1088000 | L26: 170
C27: Mano de obra | D27: 15 | E27: 90000 | F27: =D27*E27 -> 1350000 | G27: Tubo PVC 1 pulgada x 6m presion | H27: 1 | I27: 35000 | J27: =H27*I27 -> 35000 | L27: =SUM(L14:L26) -> 2231
G28: Tubo PVC 1 1/2" pulgada x 6m presion | H28: 2 | I28: 45000 | J28: =H28*I28 -> 90000
C29: Árboles de ceiba | D29: 10 | E29: 3000 | F29: =D29*E29 -> 30000 | G29: T Lisa de PVC de 1" | H29: 1 | I29: 1333 | J29: =H29*I29 -> 1333
C30: Aljibe | D30: 1 | E30: 300000 | F30: =D30*E30 -> 300000 | G30: Llave de paso de PVC 1" | H30: 2 | I30: 32000 | J30: =H30*I30 -> 64000
G31: Llave de paso de PVC 1 1/2" | H31: 1 | I31: 40000 | J31: =H31*I31 -> 40000
F32: =D32*E32 -> 0 | G32: Unión universal de 1" | H32: 1 | I32: 11000 | J32: =H32*I32 -> 11000
G33: Unión universal de 1 1/2"" | H33: 2 | I33: 13000 | J33: =H33*I33 -> 26000
G34: Unión PVC de 1 1/2" | H34: 3 | I34: 5900 | J34: =H34*I34 -> 17700
F35: =D35*E35 -> 0 | G35: Codo PVC de 1" | H35: 2 | I35: 2000 | J35: =H35*I35 -> 4000
G36: Codo PVC de 1 1/2" | H36: 5 | I36: 5000 | J36: =H36*I36 -> 25000
F37: =D37*E37 -> 0 | G37: Reducción de PVC de 1" a 3/4" | H37: 2 | I37: 1333 | J37: =H37*I37 -> 2666
F38: =D38*E38 -> 0 | G38: Inserto 3/4" de manguera a tubo x unidad | H38: 15 | I38: 4000 | J38: =H38*I38 -> 60000
G39: T para manguera de 3/4" | H39: 3 | I39: 3000 | J39: =H39*I39 -> 9000
G40: Inserto 1/2" de manguera a tubo x unidad | H40: 6 | I40: 2000 | J40: =H40*I40 -> 12000
G41: Inserto de PVC de 1" ½" | H41: 3
F42: =D42*E42 -> 0 | G42: Manguera PP 3/4x100 C40 Peletizada Rollo x 100 Metros | H42: 10 | I42: 146667 | J42: =H42*I42 -> 1466670
G43: Manguera PP 1 1/2"x100 C40 Peletizada Rollo x 100 Metros | H43: 1 | I43: 200000 | J43: =H43*I43 -> 200000
F44: =D44*E44 -> 0 | G44: T 3/4" salida rosca presion x unidad | H44: 5 | I44: 2000 | J44: =H44*I44 -> 10000
F45: =D45*E45 -> 0 | G45: Codo PVC de 3/4" con rosca | H45: 4 | I45: 1333 | J45: =H45*I45 -> 5332
F46: =D46*E46 -> 0 | G46: Hidrantes de 3/4" | H46: 7 | I46: 38000 | J46: =H46*I46 -> 266000
...

Sheet Ivan_Ibarra
B7: ACTIVIDADES DE INVERSION FAMILIA: _Ivan Ibarra
B8: ACTIVIDAD # 1. Implementación de 26 hectáreas de sistema silvopastoril de 8 potreros se sacan 26 potreros de 1 hectareas
B9: SUB ACTIVIDAD | C9: APORTE DE LA FAMILIA | G9: APORTE DEL PROYECTO
C10: ARTICULO | D10: CANTIDAD | E10: VALOR UNI | F10: VALOR TOTAL | G10: ARTICULO | H10: CANTIDAD | I10: VALOR UNI | J10: VALOR TOTAL
C11: Estantillos y mano de obra | D11: =613+192 -> 805 | E11: 30000 | F11: =D11*E11 -> 24150000 | G11: Alambre de cerca Calibre 14 x Rollo x 1000 Metros Puma | H11: 14 | I11: 270000 | J11: =H11*I11 -> 3780000 | K11: =L30 -> 4294 | L11: Más alambre para corredor | O11: =K11/7 -> 613.42857
G12: Aislador Pera bolsa*25 Marca Súper Fox | H12: 3 | I12: 35000 | J12: =H12*I12 -> 105000
F13: =D13*E13 -> 0 | G13: Tensor pequeño 500 metros punto rojo | H13: 40 | I13: 5000 | J13: =H13*I13 -> 200000 | N13: =K11*2 -> 8588
F14: =D14*E14 -> 0 | G14: Alambre aislador rollo*50 Súper Fox | H14: 2 | I14: 60000 | J14: =H14*I14 -> 120000 | L14: 500
F15: =D15*E15 -> 0 | G15: Aisldor Puntila bolsa x 100 unidades | H15: 13 | I15: 38000 | J15: =H15*I15 -> 494000 | L15: 556
C16: Panel Solar 200WAT x Unidad | D16: 1 | E16: 586300 | F16: =D16*E16 -> 586300 | G16: Puntilla de 3" | H16: 13 | I16: 6000 | J16: =H16*I16 -> 78000 | L16: 560
F17: =D17*E17 -> 0 | G17: Bateria solar grande green point GELL (150 AMP) | H17: 1 | I17: 1250000 | J17: =H17*I17 -> 1250000 | L17: 383
F18: =D18*E18 -> 0 | G18: Regulador 30 AMP/12V | H18: 1 | I18: 150000 | J18: =H18*I18 -> 150000 | L18: 90 | N18: =2300/12 -> 191.66667
F19: =D19*E19 -> 0 | G19: Impulsor 50 km 12V Superfox | H19: 1 | I19: 450000 | J19: =H19*I19 -> 450000 | L19: 110
B20: SUBTOTAL | F20: =SUM(F11:F19) -> 24736300 | G20: SUBTOTAL | J20: =SUM(J11:J19) -> 6627000 | L20: 147
L21: 130
B22: ACTIVIDAD # 2. Implementación de 1000 metros de acueducto ganadero | L22: 145
B23: SUB ACTIVIDAD | C23: APORTE DE LA FAMILIA | G23: APORTE DEL PROYECTO | L23: 158
C24: ARTICULO | D24: CANTIDAD | E24: VALOR UNI | F24: VALOR TOTAL | G24: ARTICULO | H24: CANTIDAD | I24: VALOR UNI | J24: VALOR TOTAL | L24: 170
B25: Adecuación de acueducto ganader | C25: Torre para tanque | D25: 1 | E25: 2000000 | F25: =D25*E25 -> 2000000 | G25: Tanque Plástico 2000 Litros Alto con tapa x Unidad Proco | H25: 1 | I25: 1088000 | J25: =H25*I25 -> 1088000 | L25: 180
C26: Mano de obra | D26: 15 | E26: 90000 | F26: =D26*E26 -> 1350000 | G26: Tubo PVC 1 pulgada x 6m presion | H26: 1 | I26: 35000 | J26: =H26*I26 -> 35000 | L26: 170
G27: Tubo PVC 1 1/2" pulgada x 6m presion | H27: 2 | I27: 45000 | J27: =H27*I27 -> 90000 | L27: 160
C28: Árboles de ceiba | D28: 10 | E28: 3000 | F28: =D28*E28 -> 30000 | G28: T Lisa de PVC de 1" | H28: 1 | I28: 1333 | J28: =H28*I28 -> 1333 | L28: 555
C29: Aljibe | D29: 1 | E29: 300000 | F29: =D29*E29 -> 300000 | G29: Llave de paso de PVC 1" | H29: 2 | I29: 32000 | J29: =H29*I29 -> 64000 | L29: 280
G30: Llave de paso de PVC 1 1/2" | H30: 1 | I30: 40000 | J30: =H30*I30 -> 40000 | L30: =SUM(L14:L29) -> 4294
F31: =D31*E31 -> 0 | G31: Unión universal de 1" | H31: 1 | I31: 11000 | J31: =H31*I31 -> 11000
G32: Unión universal de 1 1/2"" | H32: 3 | I32: 13000 | J32: =H32*I32 -> 39000
G33: Unión PVC de 1 1/2" | H33: 3 | I33: 5900 | J33: =H33*I33 -> 17700
F34: =D34*E34 -> 0 | G34: Codo PVC de 1" | H34: 2 | I34: 2000 | J34: =H34*I34 -> 4000
G35: Codo PVC de 1 1/2" | H35: 5 | I35: 5000 | J35: =H35*I35 -> 25000
F36: =D36*E36 -> 0 | G36: Reducción de PVC de 1" a 3/4" | H36: 2 | I36: 1333 | J36: =H36*I36 -> 2666
F37: =D37*E37 -> 0 | G37: Inserto 3/4" de manguera a tubo x unidad | H37: 15 | I37: 4000 | J37: =H37*I37 -> 60000
G38: T para manguera de 3/4" | H38: 8 | I38: 3000 | J38: =H38*I38 -> 24000
G39: Inserto 1/2" de manguera a tubo x unidad | H39: 6 | I39: 2000 | J39: =H39*I39 -> 12000
G40: Inserto de PVC de 1" ½" | H40: 3 | I40: 3000 | J40: =H40*I40 -> 9000
F41: =D41*E41 -> 0 | G41: Manguera PP 3/4x100 C40 Peletizada Rollo x 100 Metros | H41: 10 | I41: 146667 | J41: =H41*I41 -> 1466670
G42: Manguera PP 1 1/2"x100 C40 Peletizada Rollo x 100 Metros | H42: 3 | I42: 200000 | J42: =H42*I42 -> 600000
F43: =D43*E43 -> 0 | G43: T 3/4" salida rosca presion x unidad | H43: 5 | I43: 2000 | J43: =H43*I43 -> 10000
F44: =D44*E44 -> 0 | G44: Codo PVC de 3/4" con rosca | H44: 4 | I44: 1333 | J44: =H44*I44 -> 5332
F45: =D45*E45 -> 0 | G45: Hidrantes de 3/4" | H45: 16 | I45: 38000 | J45: =H45*I45 -> 608000
F46: =D46*E46 -> 0 | G46: unión de manguera 3/4" | H46: 5 | I46: 2700 | J46: =H46*I46 -> 13500
...

Sheet Luis_Eduardo_Gomez
B7: ACTIVIDADES DE INVERSION FAMILIA: _Luis Eduardo Gomez
B8: ACTIVIDAD # 1. Implementación de 19 hectáreas de sistema silvopastoril de 7 potreros se sacan 20 potreros de 0,5 hectareas
B9: SUB ACTIVIDAD | C9: APORTE DE LA FAMILIA | G9: APORTE DEL PROYECTO
C10: ARTICULO | D10: CANTIDAD | E10: VALOR UNI | F10: VALOR TOTAL | G10: ARTICULO | H10: CANTIDAD | I10: VALOR UNI | J10: VALOR TOTAL
C11: Estantillos y mano de obra | D11: =376+180 -> 556 | E11: 30000 | F11: =D11*E11 -> 16680000 | G11: Alambre de cerca Calibre 14 x Rollo x 1000 Metros Puma | H11: 12 | I11: 270000 | J11: =H11*I11 -> 3240000 | K11: 2627 | L11: Más alambre para corredor | O11: =K11/7 -> 375.28571
G12: Aislador Pera bolsa*25 Marca Súper Fox | H12: 5 | I12: 35000 | J12: =H12*I12 -> 175000
F13: =D13*E13 -> 0 | G13: Tensor pequeño 500 metros punto rojo | H13: 60 | I13: 5000 | J13: =H13*I13 -> 300000 | N13: =K11*3 -> 7881
F14: =D14*E14 -> 0 | G14: Alambre aislador rollo*50 Súper Fox | H14: 2 | I14: 60000 | J14: =H14*I14 -> 120000 | L14: 197 | N14: =K11-838 -> 1789 | P14: =D11*3 -> 1668
F15: =D15*E15 -> 0 | G15: Aisldor Puntila bolsa x 100 unidades | H15: 17 | I15: 38000 | J15: =H15*I15 -> 646000 | L15: 119
F16: =D16*E16 -> 0 | G16: Puntilla de 3" | H16: 17 | I16: 6000 | J16: =H16*I16 -> 102000 | L16: 212 | N16: =1800*2 -> 3600
F17: =D17*E17 -> 0 | L17: 136
F18: =D18*E18 -> 0 | L18: 354
B19: SUBTOTAL | F19: =SUM(F11:F18) -> 16680000 | G19: SUBTOTAL | J19: =SUM(J11:J18) -> 4583000 | L19: 137
L20: 182
B21: ACTIVIDAD # 2. Implementación de 1000 metros de acueducto ganadero | L21: 134
B22: SUB ACTIVIDAD | C22: APORTE DE LA FAMILIA | G22: APORTE DEL PROYECTO | L22: 638 | M22: Corredor
C23: ARTICULO | D23: CANTIDAD | E23: VALOR UNI | F23: VALOR TOTAL | G23: ARTICULO | H23: CANTIDAD | I23: VALOR UNI | J23: VALOR TOTAL | L23: 200
B24: Adecuación de acueducto ganader | C24: Torre para tanque | D24: 1 | E24: 2000000 | F24: =D24*E24 -> 2000000 | G24: Tanque Plástico 2000 Litros Alto con tapa x Unidad Proco | H24: 1 | I24: 1088000 | J24: =H24*I24 -> 1088000
C25: Mano de obra | D25: 15 | E25: 90000 | F25: =D25*E25 -> 1350000 | G25: Tubo PVC 1 pulgada x 6m presion | H25: 2 | I25: 35000 | J25: =H25*I25 -> 70000
G26: Tubo PVC 1 1/2" pulgada x 6m presion | H26: 2 | I26: 45000 | J26: =H26*I26 -> 90000
F27: =D27*E27 -> 0 | G27: T Lisa de PVC de 1" | H27: 1 | I27: 1333 | J27: =H27*I27 -> 1333
C28: Aljibe | D28: 1 | E28: 300000 | F28: =D28*E28 -> 300000 | G28: Llave de paso de PVC 1" | H28: 2 | I28: 32000 | J28: =H28*I28 -> 64000
G29: Llave de paso de PVC 1 1/2" | H29: 1 | I29: 40000 | J29: =H29*I29 -> 40000 | L29: =SUM(L14:L28) -> 2309
F30: =D30*E30 -> 0 | G30: Unión universal de 1" | H30: 1 | I30: 11000 | J30: =H30*I30 -> 11000
G31: Unión universal de 1 1/2"" | H31: 2 | I31: 13000 | J31: =H31*I31 -> 26000
G32: Unión PVC de 1 1/2" | H32: 3 | I32: 5900 | J32: =H32*I32 -> 17700
F33: =D33*E33 -> 0 | G33: Codo PVC de 1" | H33: 2 | I33: 2000 | J33: =H33*I33 -> 4000
G34: Codo PVC de 1 1/2" | H34: 5 | I34: 5000 | J34: =H34*I34 -> 25000
F35: =D35*E35 -> 0 | G35: Reducción de PVC de 1" a 3/4" | H35: 2 | I35: 1333 | J35: =H35*I35 -> 2666
F36: =D36*E36 -> 0 | G36: Inserto 3/4" de manguera a tubo x unidad | H36: 20 | I36: 4000 | J36: =H36*I36 -> 80000
G37: T para manguera de 3/4" | H37: 3 | I37: 3000 | J37: =H37*I37 -> 9000
G38: Inserto 1/2" de manguera a tubo x unidad | H38: 6 | I38: 2000 | J38: =H38*I38 -> 12000
G39: Inserto de PVC de 1" ½" | H39: 3
F40: =D40*E40 -> 0 | G40: Manguera PP 3/4x100 C40 Peletizada Rollo x 100 Metros | H40: 12 | I40: 146667 | J40: =H40*I40 -> 1760004
G41: Manguera PP 1 1/2"x100 C40 Peletizada Rollo x 100 Metros | H41: 2 | I41: 200000 | J41: =H41*I41 -> 400000
F42: =D42*E42 -> 0 | G42: T 3/4" salida rosca presion x unidad | H42: 7 | I42: 2000 | J42: =H42*I42 -> 14000
F43: =D43*E43 -> 0 | G43: Codo PVC de 3/4" con rosca | H43: 4 | I43: 1333 | J43: =H43*I43 -> 5332
F44: =D44*E44 -> 0 | G44: Hidrantes de 3/4" | H44: 8 | I44: 38000 | J44: =H44*I44 -> 304000
F45: =D45*E45 -> 0 | G45: unión de manguera 3/4" | H45: 11 | I45: 2700 | J45: =H45*I45 -> 29700
G46: Unión de manguera 1 1/2" | H46: 1 | I46: 2700 | J46: =H46*I46 -> 2700
...

Sheet Victor_Bonilla
B7: ACTIVIDADES DE INVERSION FAMILIA: _Victor Alfonso Bonilla
B8: ACTIVIDAD # 1. Implementación de 19 hectáreas de sistema silvopastoril de 7 potreros se sacan 20 potreros de 0,5 hectareas
B9: SUB ACTIVIDAD | C9: APORTE DE LA FAMILIA | G9: APORTE DEL PROYECTO
C10: ARTICULO | D10: CANTIDAD | E10: VALOR UNI | F10: VALOR TOTAL | G10: ARTICULO | H10: CANTIDAD | I10: VALOR UNI | J10: VALOR TOTAL
C11: Estantillos y mano de obra | D11: 500 | E11: 30000 | F11: =D11*E11 -> 15000000 | G11: Alambre de cerca Calibre 14 x Rollo x 1000 Metros Puma | H11: 5 | I11: 270000 | J11: =H11*I11 -> 1350000 | K11: 1226 | L11: Más alambre para corredor | O11: =K11/7 -> 175.14286
G12: Aislador Pera bolsa*25 Marca Súper Fox | H12: 2 | I12: 35000 | J12: =H12*I12 -> 70000
F13: =D13*E13 -> 0 | G13: Tensor pequeño 500 metros punto rojo | H13: 30 | I13: 5000 | J13: =H13*I13 -> 150000 | L13: 111 | N13: =K11*2 -> 2452
F14: =D14*E14 -> 0 | G14: Alambre aislador rollo*50 Súper Fox | H14: 2 | I14: 60000 | J14: =H14*I14 -> 120000 | L14: =165*2 -> 330 | M14: Aislamiento | P14: =D11*2 -> 1000
F15: =D15*E15 -> 0 | G15: Aisldor Puntila bolsa x 100 unidades | H15: 10 | I15: 38000 | J15: =H15*I15 -> 380000 | L15: 138
F16: =D16*E16 -> 0 | G16: Puntilla de 3" | H16: 10 | I16: 6000 | J16: =H16*I16 -> 60000 | L16: 121
F17: =D17*E17 -> 0 | L17: 106
F18: =D18*E18 -> 0 | L18: =210*2 -> 420 | M18: Corredor | N18: 223 | O18: =N18*4 -> 892
B19: SUBTOTAL | F19: =SUM(F11:F18) -> 15000000 | G19: SUBTOTAL | J19: =SUM(J11:J18) -> 2130000 | M19: SAF
L20: =SUM(L13:L19) -> 1226
B21: ACTIVIDAD # 2. Implementación de 800 metros de acueducto ganadero
B22: SUB ACTIVIDAD | C22: APORTE DE LA FAMILIA | G22: APORTE DEL PROYECTO
C23: ARTICULO | D23: CANTIDAD | E23: VALOR UNI | F23: VALOR TOTAL | G23: ARTICULO | H23: CANTIDAD | I23: VALOR UNI | J23: VALOR TOTAL
B24: Adecuación de acueducto ganader | C24: Torre para tanque | D24: 1 | E24: 2000000 | F24: =D24*E24 -> 2000000 | G24: Tanque Plástico 2000 Litros Alto con tapa x Unidad Proco | H24: 1 | I24: 1088000 | J24: =H24*I24 -> 1088000
C25: Mano de obra | D25: 15 | E25: 90000 | F25: =D25*E25 -> 1350000 | G25: Tubo PVC 1 pulgada x 6m presion | H25: 2 | I25: 35000 | J25: =H25*I25 -> 70000
G26: Tubo PVC 1 1/2" pulgada x 6m presion | H26: 2 | I26: 45000 | J26: =H26*I26 -> 90000
F27: =D27*E27 -> 0 | G27: T Lisa de PVC de 1" | H27: 1 | I27: 1333 | J27: =H27*I27 -> 1333
C28: Aljibe | D28: 1 | E28: 300000 | F28: =D28*E28 -> 300000 | G28: Llave de paso de PVC 1" | H28: 2 | I28: 32000 | J28: =H28*I28 -> 64000
G29: Llave de paso de PVC 1 1/2" | H29: 1 | I29: 40000 | J29: =H29*I29 -> 40000 | L29: =SUM(L14:L28) -> 2341
F30: =D30*E30 -> 0 | G30: Unión universal de 1" | H30: 1 | I30: 11000 | J30: =H30*I30 -> 11000
G31: Unión universal de 1 1/2"" | H31: 2 | I31: 13000 | J31: =H31*I31 -> 26000
G32: Unión PVC de 1 1/2" | H32: 3 | I32: 5900 | J32: =H32*I32 -> 17700
F33: =D33*E33 -> 0 | G33: Codo PVC de 1" | H33: 2 | I33: 2000 | J33: =H33*I33 -> 4000
G34: Codo PVC de 1 1/2" | H34: 5 | I34: 5000 | J34: =H34*I34 -> 25000
F35: =D35*E35 -> 0 | G35: Reducción de PVC de 1" a 3/4" | H35: 2 | I35: 1333 | J35: =H35*I35 -> 2666
F36: =D36*E36 -> 0 | G36: Inserto 3/4" de manguera a tubo x unidad | H36: 18 | I36: 4000 | J36: =H36*I36 -> 72000
G37: T para manguera de 3/4" | H37: 2 | I37: 3000 | J37: =H37*I37 -> 6000
G38: Inserto 1/2" de manguera a tubo x unidad | H38: 6 | I38: 2000 | J38: =H38*I38 -> 12000
G39: Inserto de PVC de 1" ½" | H39: 3
F40: =D40*E40 -> 0 | G40: Manguera PP 3/4x100 C40 Peletizada Rollo x 100 Metros | H40: 8 | I40: 146667 | J40: =H40*I40 -> 1173336
G41: Manguera PP 1 1/2"x100 C40 Peletizada Rollo x 100 Metros | H41: 2 | I41: 200000 | J41: =H41*I41 -> 400000
F42: =D42*E42 -> 0 | G42: T 3/4" salida rosca presion x unidad | H42: 7 | I42: 2000 | J42: =H42*I42 -> 14000
F43: =D43*E43 -> 0 | G43: Codo PVC de 3/4" con rosca | H43: 3 | I43: 1333 | J43: =H43*I43 -> 3999
F44: =D44*E44 -> 0 | G44: Hidrantes de 3/4" | H44: 6 | I44: 38000 | J44: =H44*I44 -> 228000
F45: =D45*E45 -> 0 | G45: unión de manguera 3/4" | H45: 7 | I45: 2700 | J45: =H45*I45 -> 18900
G46: Unión de manguera 1 1/2" | H46: 1 | I46: 2700 | J46: =H46*I46 -> 2700
...

Sheet Cenaida
B7: ACTIVIDADES DE INVERSION FAMILIA: _Cenaida Quitero | N7: =13*4 -> 52
B8: ACTIVIDAD # 1. Implementación de 14,5 hectáreas de sistema silvopastoril de 5 potreros se sacan 16 potreros de 1 hectarea aprximada | N8: =13*6 -> 78
B9: SUB ACTIVIDAD | C9: APORTE DE LA FAMILIA | G9: APORTE DEL PROYECTO
C10: ARTICULO | D10: CANTIDAD | E10: VALOR UNI | F10: VALOR TOTAL | G10: ARTICULO | H10: CANTIDAD | I10: VALOR UNI | J10: VALOR TOTAL | K10: 1.82
C11: Estantillos y mano de obra | D11: 400 | E11: 30000 | F11: =D11*E11 -> 12000000 | G11: Alambre de cerca Calibre 14 x Rollo x 1000 Metros Puma | H11: 10 | I11: 270000 | J11: =H11*I11 -> 2700000 | K11: 1.93
G12: Aislador Pera bolsa*25 Marca Súper Fox | H12: 6 | I12: 35000 | J12: =H12*I12 -> 210000 | K12: 1.22 | L12: 100 | N12: =L24*3 -> 4701 | O12: Alambre
F13: =D13*E13 -> 0 | G13: Tensor pequeño 500 metros punto rojo | H13: 80 | I13: 5000 | J13: =H13*I13 -> 400000 | K13: 9.48 | L13: 98
F14: =D14*E14 -> 0 | G14: Alambre aislador rollo*50 Súper Fox | H14: 2 | I14: 60000 | J14: =H14*I14 -> 120000 | L14: 94 | N14: 224 | O14: estantillos ssp
F15: =D15*E15 -> 0 | G15: Aisldor Puntila bolsa x 100 unidades | H15: 11 | I15: 38000 | J15: =H15*I15 -> 418000 | L15: 55
F16: =D16*E16 -> 0 | G16: Puntilla de 3" | H16: 11 | I16: 6000 | J16: =H16*I16 -> 66000 | L16: 236 | N16: =L24*2 -> 3134 | O16: Alambre cerca viva
F17: =D17*E17 -> 0 | L17: 46
F18: =D18*E18 -> 0 | L18: 56
B19: SUBTOTAL | F19: =SUM(F11:F18) -> 12000000 | G19: SUBTOTAL | J19: =SUM(J11:J18) -> 3914000 | L19: 99 | N19: 15 | O19: Estantillos SAF
L20: 171
B21: ACTIVIDAD # 2. Implementación de 1000 metros de acueducto ganadero | L21: 90 | N21: 157 | O21: Estantillos cerca viva
B22: SUB ACTIVIDAD | C22: APORTE DE LA FAMILIA | G22: APORTE DEL PROYECTO | L22: 87
C23: ARTICULO | D23: CANTIDAD | E23: VALOR UNI | F23: VALOR TOTAL | G23: ARTICULO | H23: CANTIDAD | I23: VALOR UNI | J23: VALOR TOTAL | L23: 435 | N23: =N21+N19+N14 -> 396 | O23: Estantillos en total
B24: Adecuación de acueducto ganader | C24: Torre para tanque | D24: 1 | E24: 2000000 | F24: =D24*E24 -> 2000000 | G24: Tanque Plástico 2000 Litros Alto con tapa x Unidad Proco | H24: 1 | I24: 1088000 | J24: =H24*I24 -> 1088000 | L24: =SUM(L12:L23) -> 1567 | M24: Cerca viva
C25: Mano de obra | D25: 15 | E25: 90000 | F25: =D25*E25 -> 1350000 | G25: Tubo PVC 1 pulgada x 6m presion | H25: 2 | I25: 35000 | J25: =H25*I25 -> 70000 | N25: =N14*3 -> 672 | O25: Aislador puntilla ssp
G26: Tubo PVC 1 1/2" pulgada x 6m presion | H26: 2 | I26: 45000 | J26: =H26*I26 -> 90000 | N26: =N21*2 -> 314 | O26: Aislador puntillacercav viva
F27: =D27*E27 -> 0 | G27: T Lisa de PVC de 1" | H27: 1 | I27: 1333 | J27: =H27*I27 -> 1333
C28: Aljibe | D28: 1 | E28: 300000 | F28: =D28*E28 -> 300000 | G28: Llave de paso de PVC 1" | H28: 2 | I28: 32000 | J28: =H28*I28 -> 64000
G29: Llave de paso de PVC 1 1/2" | H29: 1 | I29: 40000 | J29: =H29*I29 -> 40000 | L29: =SUM(L14:L28) -> 2936
F30: =D30*E30 -> 0 | G30: Unión universal de 1" | H30: 1 | I30: 11000 | J30: =H30*I30 -> 11000
G31: Unión universal de 1 1/2"" | H31: 2 | I31: 13000 | J31: =H31*I31 -> 26000
G32: Unión PVC de 1 1/2" | H32: 3 | I32: 5900 | J32: =H32*I32 -> 17700 | L32: 229
F33: =D33*E33 -> 0 | G33: Codo PVC de 1" | H33: 2 | I33: 2000 | J33: =H33*I33 -> 4000 | L33: 677
G34: Codo PVC de 1 1/2" | H34: 5 | I34: 5000 | J34: =H34*I34 -> 25000 | L34: 66
F35: =D35*E35 -> 0 | G35: Reducción de PVC de 1" a 3/4" | H35: 2 | I35: 1333 | J35: =H35*I35 -> 2666 | L35: 123
F36: =D36*E36 -> 0 | G36: Inserto 3/4" de manguera a tubo x unidad | H36: 20 | I36: 4000 | J36: =H36*I36 -> 80000 | L36: =SUM(L32:L35) -> 1095 | M36: Manguera de 3/4"
G37: T para manguera de 3/4" | H37: 4 | I37: 3000 | J37: =H37*I37 -> 12000
G38: Inserto 1/2" de manguera a tubo x unidad | H38: 6 | I38: 2000 | J38: =H38*I38 -> 12000
G39: Inserto de PVC de 1" ½" | H39: 3
F40: =D40*E40 -> 0 | G40: Manguera PP 3/4x100 C40 Peletizada Rollo x 100 Metros | H40: 11 | I40: 146667 | J40: =H40*I40 -> 1613337
G41: Manguera PP 1 1/2"x100 C40 Peletizada Rollo x 100 Metros | H41: 3 | I41: 200000 | J41: =H41*I41 -> 600000
F42: =D42*E42 -> 0 | G42: T 3/4" salida rosca presion x unidad | H42: 7 | I42: 2000 | J42: =H42*I42 -> 14000
F43: =D43*E43 -> 0 | G43: Codo PVC de 3/4" con rosca | H43: 4 | I43: 1333 | J43: =H43*I43 -> 5332
F44: =D44*E44 -> 0 | G44: Hidrantes de 3/4" | H44: 8 | I44: 38000 | J44: =H44*I44 -> 304000
F45: =D45*E45 -> 0 | G45: unión de manguera 3/4" | H45: 10 | I45: 2700 | J45: =H45*I45 -> 27000
G46: Unión de manguera 1 1/2" | H46: 2 | I46: 2700 | J46: =H46*I46 -> 5400
...
